2025-05-05 15:18:17,291 - Ê©üÂô®‰∫∫Â∑≤ÂïüÂãï...
2025-05-05 15:35:33,701 - Ê©üÂô®‰∫∫Â∑≤ÂïüÂãï...
2025-05-05 15:38:40,605 - Ê©üÂô®‰∫∫Â∑≤ÂïüÂãï...
2025-05-05 15:38:42,664 - Infinity polling exception: name 'get_current_month_report_message' is not defined
2025-05-05 15:38:42,668 - Exception traceback:
Traceback (most recent call last):
  File "C:\Users\Administrator\AppData\Local\Programs\Python\Python313\Lib\site-packages\telebot\__init__.py", line 1016, in infinity_polling
    self.polling(non_stop=True, timeout=timeout, long_polling_timeout=long_polling_timeout,
    ~~~~~~~~~~~~^^^^^^^^^^^^^^^^^^^^^^^^^^^^^^^^^^^^^^^^^^^^^^^^^^^^^^^^^^^^^^^^^^^^^^^^^^^
                 logger_level=logger_level, allowed_updates=allowed_updates, restart_on_change=False,
                 ^^^^^^^^^^^^^^^^^^^^^^^^^^^^^^^^^^^^^^^^^^^^^^^^^^^^^^^^^^^^^^^^^^^^^^^^^^^^^^^^^^^^
                 *args, **kwargs)
                 ^^^^^^^^^^^^^^^^
  File "C:\Users\Administrator\AppData\Local\Programs\Python\Python313\Lib\site-packages\telebot\__init__.py", line 1104, in polling
    self.__threaded_polling(non_stop=non_stop, interval=interval, timeout=timeout, long_polling_timeout=long_polling_timeout,
    ~~~~~~~~~~~~~~~~~~~~~~~^^^^^^^^^^^^^^^^^^^^^^^^^^^^^^^^^^^^^^^^^^^^^^^^^^^^^^^^^^^^^^^^^^^^^^^^^^^^^^^^^^^^^^^^^^^^^^^^^^
                            logger_level=logger_level, allowed_updates=allowed_updates)
                            ^^^^^^^^^^^^^^^^^^^^^^^^^^^^^^^^^^^^^^^^^^^^^^^^^^^^^^^^^^^
  File "C:\Users\Administrator\AppData\Local\Programs\Python\Python313\Lib\site-packages\telebot\__init__.py", line 1179, in __threaded_polling
    raise e
  File "C:\Users\Administrator\AppData\Local\Programs\Python\Python313\Lib\site-packages\telebot\__init__.py", line 1141, in __threaded_polling
    self.worker_pool.raise_exceptions()
    ~~~~~~~~~~~~~~~~~~~~~~~~~~~~~~~~~^^
  File "C:\Users\Administrator\AppData\Local\Programs\Python\Python313\Lib\site-packages\telebot\util.py", line 149, in raise_exceptions
    raise self.exception_info
  File "C:\Users\Administrator\AppData\Local\Programs\Python\Python313\Lib\site-packages\telebot\util.py", line 92, in run
    task(*args, **kwargs)
    ~~~~^^^^^^^^^^^^^^^^^
  File "C:\Users\Administrator\AppData\Local\Programs\Python\Python313\Lib\site-packages\telebot\__init__.py", line 7860, in _run_middlewares_and_handler
    result = handler['function'](message)
  File "C:\Telegram Bot\AccountBot\bot.py", line 1643, in handle_history_report
    msg += get_current_month_report_message()
           ^^^^^^^^^^^^^^^^^^^^^^^^^^^^^^^^
NameError: name 'get_current_month_report_message' is not defined

2025-05-05 15:41:36,708 - Ê©üÂô®‰∫∫Â∑≤ÂïüÂãï...
2025-05-05 15:41:42,457 - Infinity polling exception: KeyboardButton.__init__() got an unexpected keyword argument 'callback_data'
2025-05-05 15:41:42,462 - Exception traceback:
Traceback (most recent call last):
  File "C:\Users\Administrator\AppData\Local\Programs\Python\Python313\Lib\site-packages\telebot\__init__.py", line 1016, in infinity_polling
    self.polling(non_stop=True, timeout=timeout, long_polling_timeout=long_polling_timeout,
    ~~~~~~~~~~~~^^^^^^^^^^^^^^^^^^^^^^^^^^^^^^^^^^^^^^^^^^^^^^^^^^^^^^^^^^^^^^^^^^^^^^^^^^^
                 logger_level=logger_level, allowed_updates=allowed_updates, restart_on_change=False,
                 ^^^^^^^^^^^^^^^^^^^^^^^^^^^^^^^^^^^^^^^^^^^^^^^^^^^^^^^^^^^^^^^^^^^^^^^^^^^^^^^^^^^^
                 *args, **kwargs)
                 ^^^^^^^^^^^^^^^^
  File "C:\Users\Administrator\AppData\Local\Programs\Python\Python313\Lib\site-packages\telebot\__init__.py", line 1104, in polling
    self.__threaded_polling(non_stop=non_stop, interval=interval, timeout=timeout, long_polling_timeout=long_polling_timeout,
    ~~~~~~~~~~~~~~~~~~~~~~~^^^^^^^^^^^^^^^^^^^^^^^^^^^^^^^^^^^^^^^^^^^^^^^^^^^^^^^^^^^^^^^^^^^^^^^^^^^^^^^^^^^^^^^^^^^^^^^^^^
                            logger_level=logger_level, allowed_updates=allowed_updates)
                            ^^^^^^^^^^^^^^^^^^^^^^^^^^^^^^^^^^^^^^^^^^^^^^^^^^^^^^^^^^^
  File "C:\Users\Administrator\AppData\Local\Programs\Python\Python313\Lib\site-packages\telebot\__init__.py", line 1179, in __threaded_polling
    raise e
  File "C:\Users\Administrator\AppData\Local\Programs\Python\Python313\Lib\site-packages\telebot\__init__.py", line 1141, in __threaded_polling
    self.worker_pool.raise_exceptions()
    ~~~~~~~~~~~~~~~~~~~~~~~~~~~~~~~~~^^
  File "C:\Users\Administrator\AppData\Local\Programs\Python\Python313\Lib\site-packages\telebot\util.py", line 149, in raise_exceptions
    raise self.exception_info
  File "C:\Users\Administrator\AppData\Local\Programs\Python\Python313\Lib\site-packages\telebot\util.py", line 92, in run
    task(*args, **kwargs)
    ~~~~^^^^^^^^^^^^^^^^^
  File "C:\Users\Administrator\AppData\Local\Programs\Python\Python313\Lib\site-packages\telebot\__init__.py", line 7860, in _run_middlewares_and_handler
    result = handler['function'](message)
  File "C:\Telegram Bot\AccountBot\bot.py", line 1635, in show_main_menu
    bot.send_message(message.chat.id, 'Ë´ãÈÅ∏ÊìáÂäüËÉΩÔºö', reply_markup=create_main_menu())
                                                                   ~~~~~~~~~~~~~~~~^^
  File "C:\Telegram Bot\AccountBot\bot.py", line 114, in create_main_menu
    KeyboardButton('üîÑÔ∏èÈáçÊñ∞ÂïüÂãï', callback_data=None)  # ÊåâÈàïÂêçÁ®±ÊîπÁÇ∫„ÄéüîÑÔ∏èÈáçÊñ∞ÂïüÂãï„Äè
    ~~~~~~~~~~~~~~^^^^^^^^^^^^^^^^^^^^^^^^^^^^^^^^^^^
TypeError: KeyboardButton.__init__() got an unexpected keyword argument 'callback_data'

2025-05-05 15:41:50,844 - Infinity polling exception: KeyboardButton.__init__() got an unexpected keyword argument 'callback_data'
2025-05-05 15:41:50,847 - Exception traceback:
Traceback (most recent call last):
  File "C:\Users\Administrator\AppData\Local\Programs\Python\Python313\Lib\site-packages\telebot\__init__.py", line 1016, in infinity_polling
    self.polling(non_stop=True, timeout=timeout, long_polling_timeout=long_polling_timeout,
    ~~~~~~~~~~~~^^^^^^^^^^^^^^^^^^^^^^^^^^^^^^^^^^^^^^^^^^^^^^^^^^^^^^^^^^^^^^^^^^^^^^^^^^^
                 logger_level=logger_level, allowed_updates=allowed_updates, restart_on_change=False,
                 ^^^^^^^^^^^^^^^^^^^^^^^^^^^^^^^^^^^^^^^^^^^^^^^^^^^^^^^^^^^^^^^^^^^^^^^^^^^^^^^^^^^^
                 *args, **kwargs)
                 ^^^^^^^^^^^^^^^^
  File "C:\Users\Administrator\AppData\Local\Programs\Python\Python313\Lib\site-packages\telebot\__init__.py", line 1104, in polling
    self.__threaded_polling(non_stop=non_stop, interval=interval, timeout=timeout, long_polling_timeout=long_polling_timeout,
    ~~~~~~~~~~~~~~~~~~~~~~~^^^^^^^^^^^^^^^^^^^^^^^^^^^^^^^^^^^^^^^^^^^^^^^^^^^^^^^^^^^^^^^^^^^^^^^^^^^^^^^^^^^^^^^^^^^^^^^^^^
                            logger_level=logger_level, allowed_updates=allowed_updates)
                            ^^^^^^^^^^^^^^^^^^^^^^^^^^^^^^^^^^^^^^^^^^^^^^^^^^^^^^^^^^^
  File "C:\Users\Administrator\AppData\Local\Programs\Python\Python313\Lib\site-packages\telebot\__init__.py", line 1179, in __threaded_polling
    raise e
  File "C:\Users\Administrator\AppData\Local\Programs\Python\Python313\Lib\site-packages\telebot\__init__.py", line 1141, in __threaded_polling
    self.worker_pool.raise_exceptions()
    ~~~~~~~~~~~~~~~~~~~~~~~~~~~~~~~~~^^
  File "C:\Users\Administrator\AppData\Local\Programs\Python\Python313\Lib\site-packages\telebot\util.py", line 149, in raise_exceptions
    raise self.exception_info
  File "C:\Users\Administrator\AppData\Local\Programs\Python\Python313\Lib\site-packages\telebot\util.py", line 92, in run
    task(*args, **kwargs)
    ~~~~^^^^^^^^^^^^^^^^^
  File "C:\Users\Administrator\AppData\Local\Programs\Python\Python313\Lib\site-packages\telebot\__init__.py", line 7860, in _run_middlewares_and_handler
    result = handler['function'](message)
  File "C:\Telegram Bot\AccountBot\bot.py", line 1840, in handle_change_notify_toggle
    bot.reply_to(message, f'Áï∞ÂãïÊèêÈÜí{status}', reply_markup=create_main_menu())
                                                            ~~~~~~~~~~~~~~~~^^
  File "C:\Telegram Bot\AccountBot\bot.py", line 114, in create_main_menu
    KeyboardButton('üîÑÔ∏èÈáçÊñ∞ÂïüÂãï', callback_data=None)  # ÊåâÈàïÂêçÁ®±ÊîπÁÇ∫„ÄéüîÑÔ∏èÈáçÊñ∞ÂïüÂãï„Äè
    ~~~~~~~~~~~~~~^^^^^^^^^^^^^^^^^^^^^^^^^^^^^^^^^^^
TypeError: KeyboardButton.__init__() got an unexpected keyword argument 'callback_data'

2025-05-05 15:42:47,150 - Ê©üÂô®‰∫∫Â∑≤ÂïüÂãï...
2025-05-05 15:42:49,792 - Infinity polling exception: KeyboardButton.__init__() got an unexpected keyword argument 'callback_data'
2025-05-05 15:42:49,795 - Exception traceback:
Traceback (most recent call last):
  File "C:\Users\Administrator\AppData\Local\Programs\Python\Python313\Lib\site-packages\telebot\__init__.py", line 1016, in infinity_polling
    self.polling(non_stop=True, timeout=timeout, long_polling_timeout=long_polling_timeout,
    ~~~~~~~~~~~~^^^^^^^^^^^^^^^^^^^^^^^^^^^^^^^^^^^^^^^^^^^^^^^^^^^^^^^^^^^^^^^^^^^^^^^^^^^
                 logger_level=logger_level, allowed_updates=allowed_updates, restart_on_change=False,
                 ^^^^^^^^^^^^^^^^^^^^^^^^^^^^^^^^^^^^^^^^^^^^^^^^^^^^^^^^^^^^^^^^^^^^^^^^^^^^^^^^^^^^
                 *args, **kwargs)
                 ^^^^^^^^^^^^^^^^
  File "C:\Users\Administrator\AppData\Local\Programs\Python\Python313\Lib\site-packages\telebot\__init__.py", line 1104, in polling
    self.__threaded_polling(non_stop=non_stop, interval=interval, timeout=timeout, long_polling_timeout=long_polling_timeout,
    ~~~~~~~~~~~~~~~~~~~~~~~^^^^^^^^^^^^^^^^^^^^^^^^^^^^^^^^^^^^^^^^^^^^^^^^^^^^^^^^^^^^^^^^^^^^^^^^^^^^^^^^^^^^^^^^^^^^^^^^^^
                            logger_level=logger_level, allowed_updates=allowed_updates)
                            ^^^^^^^^^^^^^^^^^^^^^^^^^^^^^^^^^^^^^^^^^^^^^^^^^^^^^^^^^^^
  File "C:\Users\Administrator\AppData\Local\Programs\Python\Python313\Lib\site-packages\telebot\__init__.py", line 1179, in __threaded_polling
    raise e
  File "C:\Users\Administrator\AppData\Local\Programs\Python\Python313\Lib\site-packages\telebot\__init__.py", line 1141, in __threaded_polling
    self.worker_pool.raise_exceptions()
    ~~~~~~~~~~~~~~~~~~~~~~~~~~~~~~~~~^^
  File "C:\Users\Administrator\AppData\Local\Programs\Python\Python313\Lib\site-packages\telebot\util.py", line 149, in raise_exceptions
    raise self.exception_info
  File "C:\Users\Administrator\AppData\Local\Programs\Python\Python313\Lib\site-packages\telebot\util.py", line 92, in run
    task(*args, **kwargs)
    ~~~~^^^^^^^^^^^^^^^^^
  File "C:\Users\Administrator\AppData\Local\Programs\Python\Python313\Lib\site-packages\telebot\__init__.py", line 7860, in _run_middlewares_and_handler
    result = handler['function'](message)
  File "C:\Telegram Bot\AccountBot\bot.py", line 1840, in handle_change_notify_toggle
    bot.reply_to(message, f'Áï∞ÂãïÊèêÈÜí{status}', reply_markup=create_main_menu())
                                                            ~~~~~~~~~~~~~~~~^^
  File "C:\Telegram Bot\AccountBot\bot.py", line 114, in create_main_menu
    KeyboardButton('üîÑÔ∏èÈáçÊñ∞ÂïüÂãï', callback_data=None)  # ÊåâÈàïÂêçÁ®±ÊîπÁÇ∫„ÄéüîÑÔ∏èÈáçÊñ∞ÂïüÂãï„Äè
    ~~~~~~~~~~~~~~^^^^^^^^^^^^^^^^^^^^^^^^^^^^^^^^^^^
TypeError: KeyboardButton.__init__() got an unexpected keyword argument 'callback_data'

2025-05-05 15:50:14,042 - Infinity polling exception: name 'get_current_month_report_message' is not defined
2025-05-05 15:50:14,045 - Exception traceback:
Traceback (most recent call last):
  File "C:\Users\Administrator\AppData\Local\Programs\Python\Python313\Lib\site-packages\telebot\__init__.py", line 1016, in infinity_polling
    self.polling(non_stop=True, timeout=timeout, long_polling_timeout=long_polling_timeout,
    ~~~~~~~~~~~~^^^^^^^^^^^^^^^^^^^^^^^^^^^^^^^^^^^^^^^^^^^^^^^^^^^^^^^^^^^^^^^^^^^^^^^^^^^
                 logger_level=logger_level, allowed_updates=allowed_updates, restart_on_change=False,
                 ^^^^^^^^^^^^^^^^^^^^^^^^^^^^^^^^^^^^^^^^^^^^^^^^^^^^^^^^^^^^^^^^^^^^^^^^^^^^^^^^^^^^
                 *args, **kwargs)
                 ^^^^^^^^^^^^^^^^
  File "C:\Users\Administrator\AppData\Local\Programs\Python\Python313\Lib\site-packages\telebot\__init__.py", line 1104, in polling
    self.__threaded_polling(non_stop=non_stop, interval=interval, timeout=timeout, long_polling_timeout=long_polling_timeout,
    ~~~~~~~~~~~~~~~~~~~~~~~^^^^^^^^^^^^^^^^^^^^^^^^^^^^^^^^^^^^^^^^^^^^^^^^^^^^^^^^^^^^^^^^^^^^^^^^^^^^^^^^^^^^^^^^^^^^^^^^^^
                            logger_level=logger_level, allowed_updates=allowed_updates)
                            ^^^^^^^^^^^^^^^^^^^^^^^^^^^^^^^^^^^^^^^^^^^^^^^^^^^^^^^^^^^
  File "C:\Users\Administrator\AppData\Local\Programs\Python\Python313\Lib\site-packages\telebot\__init__.py", line 1179, in __threaded_polling
    raise e
  File "C:\Users\Administrator\AppData\Local\Programs\Python\Python313\Lib\site-packages\telebot\__init__.py", line 1141, in __threaded_polling
    self.worker_pool.raise_exceptions()
    ~~~~~~~~~~~~~~~~~~~~~~~~~~~~~~~~~^^
  File "C:\Users\Administrator\AppData\Local\Programs\Python\Python313\Lib\site-packages\telebot\util.py", line 149, in raise_exceptions
    raise self.exception_info
  File "C:\Users\Administrator\AppData\Local\Programs\Python\Python313\Lib\site-packages\telebot\util.py", line 92, in run
    task(*args, **kwargs)
    ~~~~^^^^^^^^^^^^^^^^^
  File "C:\Users\Administrator\AppData\Local\Programs\Python\Python313\Lib\site-packages\telebot\__init__.py", line 7860, in _run_middlewares_and_handler
    result = handler['function'](message)
  File "C:\Telegram Bot\AccountBot\bot.py", line 1643, in handle_history_report
    msg += get_current_month_report_message()
           ^^^^^^^^^^^^^^^^^^^^^^^^^^^^^^^^
NameError: name 'get_current_month_report_message' is not defined

2025-05-05 15:50:24,711 - Infinity polling exception: name 'get_current_month_report_message' is not defined
2025-05-05 15:50:24,714 - Exception traceback:
Traceback (most recent call last):
  File "C:\Users\Administrator\AppData\Local\Programs\Python\Python313\Lib\site-packages\telebot\__init__.py", line 1016, in infinity_polling
    self.polling(non_stop=True, timeout=timeout, long_polling_timeout=long_polling_timeout,
    ~~~~~~~~~~~~^^^^^^^^^^^^^^^^^^^^^^^^^^^^^^^^^^^^^^^^^^^^^^^^^^^^^^^^^^^^^^^^^^^^^^^^^^^
                 logger_level=logger_level, allowed_updates=allowed_updates, restart_on_change=False,
                 ^^^^^^^^^^^^^^^^^^^^^^^^^^^^^^^^^^^^^^^^^^^^^^^^^^^^^^^^^^^^^^^^^^^^^^^^^^^^^^^^^^^^
                 *args, **kwargs)
                 ^^^^^^^^^^^^^^^^
  File "C:\Users\Administrator\AppData\Local\Programs\Python\Python313\Lib\site-packages\telebot\__init__.py", line 1104, in polling
    self.__threaded_polling(non_stop=non_stop, interval=interval, timeout=timeout, long_polling_timeout=long_polling_timeout,
    ~~~~~~~~~~~~~~~~~~~~~~~^^^^^^^^^^^^^^^^^^^^^^^^^^^^^^^^^^^^^^^^^^^^^^^^^^^^^^^^^^^^^^^^^^^^^^^^^^^^^^^^^^^^^^^^^^^^^^^^^^
                            logger_level=logger_level, allowed_updates=allowed_updates)
                            ^^^^^^^^^^^^^^^^^^^^^^^^^^^^^^^^^^^^^^^^^^^^^^^^^^^^^^^^^^^
  File "C:\Users\Administrator\AppData\Local\Programs\Python\Python313\Lib\site-packages\telebot\__init__.py", line 1179, in __threaded_polling
    raise e
  File "C:\Users\Administrator\AppData\Local\Programs\Python\Python313\Lib\site-packages\telebot\__init__.py", line 1141, in __threaded_polling
    self.worker_pool.raise_exceptions()
    ~~~~~~~~~~~~~~~~~~~~~~~~~~~~~~~~~^^
  File "C:\Users\Administrator\AppData\Local\Programs\Python\Python313\Lib\site-packages\telebot\util.py", line 149, in raise_exceptions
    raise self.exception_info
  File "C:\Users\Administrator\AppData\Local\Programs\Python\Python313\Lib\site-packages\telebot\util.py", line 92, in run
    task(*args, **kwargs)
    ~~~~^^^^^^^^^^^^^^^^^
  File "C:\Users\Administrator\AppData\Local\Programs\Python\Python313\Lib\site-packages\telebot\__init__.py", line 7860, in _run_middlewares_and_handler
    result = handler['function'](message)
  File "C:\Telegram Bot\AccountBot\bot.py", line 1643, in handle_history_report
    msg += get_current_month_report_message()
           ^^^^^^^^^^^^^^^^^^^^^^^^^^^^^^^^
NameError: name 'get_current_month_report_message' is not defined

2025-05-05 15:50:27,792 - Infinity polling exception: KeyboardButton.__init__() got an unexpected keyword argument 'callback_data'
2025-05-05 15:50:27,794 - Exception traceback:
Traceback (most recent call last):
  File "C:\Users\Administrator\AppData\Local\Programs\Python\Python313\Lib\site-packages\telebot\__init__.py", line 1016, in infinity_polling
    self.polling(non_stop=True, timeout=timeout, long_polling_timeout=long_polling_timeout,
    ~~~~~~~~~~~~^^^^^^^^^^^^^^^^^^^^^^^^^^^^^^^^^^^^^^^^^^^^^^^^^^^^^^^^^^^^^^^^^^^^^^^^^^^
                 logger_level=logger_level, allowed_updates=allowed_updates, restart_on_change=False,
                 ^^^^^^^^^^^^^^^^^^^^^^^^^^^^^^^^^^^^^^^^^^^^^^^^^^^^^^^^^^^^^^^^^^^^^^^^^^^^^^^^^^^^
                 *args, **kwargs)
                 ^^^^^^^^^^^^^^^^
  File "C:\Users\Administrator\AppData\Local\Programs\Python\Python313\Lib\site-packages\telebot\__init__.py", line 1104, in polling
    self.__threaded_polling(non_stop=non_stop, interval=interval, timeout=timeout, long_polling_timeout=long_polling_timeout,
    ~~~~~~~~~~~~~~~~~~~~~~~^^^^^^^^^^^^^^^^^^^^^^^^^^^^^^^^^^^^^^^^^^^^^^^^^^^^^^^^^^^^^^^^^^^^^^^^^^^^^^^^^^^^^^^^^^^^^^^^^^
                            logger_level=logger_level, allowed_updates=allowed_updates)
                            ^^^^^^^^^^^^^^^^^^^^^^^^^^^^^^^^^^^^^^^^^^^^^^^^^^^^^^^^^^^
  File "C:\Users\Administrator\AppData\Local\Programs\Python\Python313\Lib\site-packages\telebot\__init__.py", line 1179, in __threaded_polling
    raise e
  File "C:\Users\Administrator\AppData\Local\Programs\Python\Python313\Lib\site-packages\telebot\__init__.py", line 1141, in __threaded_polling
    self.worker_pool.raise_exceptions()
    ~~~~~~~~~~~~~~~~~~~~~~~~~~~~~~~~~^^
  File "C:\Users\Administrator\AppData\Local\Programs\Python\Python313\Lib\site-packages\telebot\util.py", line 149, in raise_exceptions
    raise self.exception_info
  File "C:\Users\Administrator\AppData\Local\Programs\Python\Python313\Lib\site-packages\telebot\util.py", line 92, in run
    task(*args, **kwargs)
    ~~~~^^^^^^^^^^^^^^^^^
  File "C:\Users\Administrator\AppData\Local\Programs\Python\Python313\Lib\site-packages\telebot\__init__.py", line 7860, in _run_middlewares_and_handler
    result = handler['function'](message)
  File "C:\Telegram Bot\AccountBot\bot.py", line 1840, in handle_change_notify_toggle
    bot.reply_to(message, f'Áï∞ÂãïÊèêÈÜí{status}', reply_markup=create_main_menu())
                                                            ~~~~~~~~~~~~~~~~^^
  File "C:\Telegram Bot\AccountBot\bot.py", line 114, in create_main_menu
    KeyboardButton('üîÑÔ∏èÈáçÊñ∞ÂïüÂãï', callback_data=None)  # ÊåâÈàïÂêçÁ®±ÊîπÁÇ∫„ÄéüîÑÔ∏èÈáçÊñ∞ÂïüÂãï„Äè
    ~~~~~~~~~~~~~~^^^^^^^^^^^^^^^^^^^^^^^^^^^^^^^^^^^
TypeError: KeyboardButton.__init__() got an unexpected keyword argument 'callback_data'

2025-05-05 15:50:30,797 - Infinity polling exception: KeyboardButton.__init__() got an unexpected keyword argument 'callback_data'
2025-05-05 15:50:30,803 - Exception traceback:
Traceback (most recent call last):
  File "C:\Users\Administrator\AppData\Local\Programs\Python\Python313\Lib\site-packages\telebot\__init__.py", line 1016, in infinity_polling
    self.polling(non_stop=True, timeout=timeout, long_polling_timeout=long_polling_timeout,
    ~~~~~~~~~~~~^^^^^^^^^^^^^^^^^^^^^^^^^^^^^^^^^^^^^^^^^^^^^^^^^^^^^^^^^^^^^^^^^^^^^^^^^^^
                 logger_level=logger_level, allowed_updates=allowed_updates, restart_on_change=False,
                 ^^^^^^^^^^^^^^^^^^^^^^^^^^^^^^^^^^^^^^^^^^^^^^^^^^^^^^^^^^^^^^^^^^^^^^^^^^^^^^^^^^^^
                 *args, **kwargs)
                 ^^^^^^^^^^^^^^^^
  File "C:\Users\Administrator\AppData\Local\Programs\Python\Python313\Lib\site-packages\telebot\__init__.py", line 1104, in polling
    self.__threaded_polling(non_stop=non_stop, interval=interval, timeout=timeout, long_polling_timeout=long_polling_timeout,
    ~~~~~~~~~~~~~~~~~~~~~~~^^^^^^^^^^^^^^^^^^^^^^^^^^^^^^^^^^^^^^^^^^^^^^^^^^^^^^^^^^^^^^^^^^^^^^^^^^^^^^^^^^^^^^^^^^^^^^^^^^
                            logger_level=logger_level, allowed_updates=allowed_updates)
                            ^^^^^^^^^^^^^^^^^^^^^^^^^^^^^^^^^^^^^^^^^^^^^^^^^^^^^^^^^^^
  File "C:\Users\Administrator\AppData\Local\Programs\Python\Python313\Lib\site-packages\telebot\__init__.py", line 1179, in __threaded_polling
    raise e
  File "C:\Users\Administrator\AppData\Local\Programs\Python\Python313\Lib\site-packages\telebot\__init__.py", line 1141, in __threaded_polling
    self.worker_pool.raise_exceptions()
    ~~~~~~~~~~~~~~~~~~~~~~~~~~~~~~~~~^^
  File "C:\Users\Administrator\AppData\Local\Programs\Python\Python313\Lib\site-packages\telebot\util.py", line 149, in raise_exceptions
    raise self.exception_info
  File "C:\Users\Administrator\AppData\Local\Programs\Python\Python313\Lib\site-packages\telebot\util.py", line 92, in run
    task(*args, **kwargs)
    ~~~~^^^^^^^^^^^^^^^^^
  File "C:\Users\Administrator\AppData\Local\Programs\Python\Python313\Lib\site-packages\telebot\__init__.py", line 7860, in _run_middlewares_and_handler
    result = handler['function'](message)
  File "C:\Telegram Bot\AccountBot\bot.py", line 1840, in handle_change_notify_toggle
    bot.reply_to(message, f'Áï∞ÂãïÊèêÈÜí{status}', reply_markup=create_main_menu())
                                                            ~~~~~~~~~~~~~~~~^^
  File "C:\Telegram Bot\AccountBot\bot.py", line 114, in create_main_menu
    KeyboardButton('üîÑÔ∏èÈáçÊñ∞ÂïüÂãï', callback_data=None)  # ÊåâÈàïÂêçÁ®±ÊîπÁÇ∫„ÄéüîÑÔ∏èÈáçÊñ∞ÂïüÂãï„Äè
    ~~~~~~~~~~~~~~^^^^^^^^^^^^^^^^^^^^^^^^^^^^^^^^^^^
TypeError: KeyboardButton.__init__() got an unexpected keyword argument 'callback_data'

2025-05-05 15:50:33,806 - Infinity polling exception: name 'get_current_month_report_message' is not defined
2025-05-05 15:50:33,811 - Exception traceback:
Traceback (most recent call last):
  File "C:\Users\Administrator\AppData\Local\Programs\Python\Python313\Lib\site-packages\telebot\__init__.py", line 1016, in infinity_polling
    self.polling(non_stop=True, timeout=timeout, long_polling_timeout=long_polling_timeout,
    ~~~~~~~~~~~~^^^^^^^^^^^^^^^^^^^^^^^^^^^^^^^^^^^^^^^^^^^^^^^^^^^^^^^^^^^^^^^^^^^^^^^^^^^
                 logger_level=logger_level, allowed_updates=allowed_updates, restart_on_change=False,
                 ^^^^^^^^^^^^^^^^^^^^^^^^^^^^^^^^^^^^^^^^^^^^^^^^^^^^^^^^^^^^^^^^^^^^^^^^^^^^^^^^^^^^
                 *args, **kwargs)
                 ^^^^^^^^^^^^^^^^
  File "C:\Users\Administrator\AppData\Local\Programs\Python\Python313\Lib\site-packages\telebot\__init__.py", line 1104, in polling
    self.__threaded_polling(non_stop=non_stop, interval=interval, timeout=timeout, long_polling_timeout=long_polling_timeout,
    ~~~~~~~~~~~~~~~~~~~~~~~^^^^^^^^^^^^^^^^^^^^^^^^^^^^^^^^^^^^^^^^^^^^^^^^^^^^^^^^^^^^^^^^^^^^^^^^^^^^^^^^^^^^^^^^^^^^^^^^^^
                            logger_level=logger_level, allowed_updates=allowed_updates)
                            ^^^^^^^^^^^^^^^^^^^^^^^^^^^^^^^^^^^^^^^^^^^^^^^^^^^^^^^^^^^
  File "C:\Users\Administrator\AppData\Local\Programs\Python\Python313\Lib\site-packages\telebot\__init__.py", line 1179, in __threaded_polling
    raise e
  File "C:\Users\Administrator\AppData\Local\Programs\Python\Python313\Lib\site-packages\telebot\__init__.py", line 1141, in __threaded_polling
    self.worker_pool.raise_exceptions()
    ~~~~~~~~~~~~~~~~~~~~~~~~~~~~~~~~~^^
  File "C:\Users\Administrator\AppData\Local\Programs\Python\Python313\Lib\site-packages\telebot\util.py", line 149, in raise_exceptions
    raise self.exception_info
  File "C:\Users\Administrator\AppData\Local\Programs\Python\Python313\Lib\site-packages\telebot\util.py", line 92, in run
    task(*args, **kwargs)
    ~~~~^^^^^^^^^^^^^^^^^
  File "C:\Users\Administrator\AppData\Local\Programs\Python\Python313\Lib\site-packages\telebot\__init__.py", line 7860, in _run_middlewares_and_handler
    result = handler['function'](message)
  File "C:\Telegram Bot\AccountBot\bot.py", line 1643, in handle_history_report
    msg += get_current_month_report_message()
           ^^^^^^^^^^^^^^^^^^^^^^^^^^^^^^^^
NameError: name 'get_current_month_report_message' is not defined

2025-05-05 15:50:44,621 - Ê©üÂô®‰∫∫Â∑≤ÂïüÂãï...
2025-05-05 15:52:43,670 - Ê©üÂô®‰∫∫Â∑≤ÂïüÂãï...
2025-05-05 15:53:05,350 - Infinity polling exception: name 'get_current_month_report_message' is not defined
2025-05-05 15:53:05,352 - Exception traceback:
Traceback (most recent call last):
  File "C:\Users\Administrator\AppData\Local\Programs\Python\Python313\Lib\site-packages\telebot\__init__.py", line 1016, in infinity_polling
    self.polling(non_stop=True, timeout=timeout, long_polling_timeout=long_polling_timeout,
    ~~~~~~~~~~~~^^^^^^^^^^^^^^^^^^^^^^^^^^^^^^^^^^^^^^^^^^^^^^^^^^^^^^^^^^^^^^^^^^^^^^^^^^^
                 logger_level=logger_level, allowed_updates=allowed_updates, restart_on_change=False,
                 ^^^^^^^^^^^^^^^^^^^^^^^^^^^^^^^^^^^^^^^^^^^^^^^^^^^^^^^^^^^^^^^^^^^^^^^^^^^^^^^^^^^^
                 *args, **kwargs)
                 ^^^^^^^^^^^^^^^^
  File "C:\Users\Administrator\AppData\Local\Programs\Python\Python313\Lib\site-packages\telebot\__init__.py", line 1104, in polling
    self.__threaded_polling(non_stop=non_stop, interval=interval, timeout=timeout, long_polling_timeout=long_polling_timeout,
    ~~~~~~~~~~~~~~~~~~~~~~~^^^^^^^^^^^^^^^^^^^^^^^^^^^^^^^^^^^^^^^^^^^^^^^^^^^^^^^^^^^^^^^^^^^^^^^^^^^^^^^^^^^^^^^^^^^^^^^^^^
                            logger_level=logger_level, allowed_updates=allowed_updates)
                            ^^^^^^^^^^^^^^^^^^^^^^^^^^^^^^^^^^^^^^^^^^^^^^^^^^^^^^^^^^^
  File "C:\Users\Administrator\AppData\Local\Programs\Python\Python313\Lib\site-packages\telebot\__init__.py", line 1179, in __threaded_polling
    raise e
  File "C:\Users\Administrator\AppData\Local\Programs\Python\Python313\Lib\site-packages\telebot\__init__.py", line 1141, in __threaded_polling
    self.worker_pool.raise_exceptions()
    ~~~~~~~~~~~~~~~~~~~~~~~~~~~~~~~~~^^
  File "C:\Users\Administrator\AppData\Local\Programs\Python\Python313\Lib\site-packages\telebot\util.py", line 149, in raise_exceptions
    raise self.exception_info
  File "C:\Users\Administrator\AppData\Local\Programs\Python\Python313\Lib\site-packages\telebot\util.py", line 92, in run
    task(*args, **kwargs)
    ~~~~^^^^^^^^^^^^^^^^^
  File "C:\Users\Administrator\AppData\Local\Programs\Python\Python313\Lib\site-packages\telebot\__init__.py", line 7860, in _run_middlewares_and_handler
    result = handler['function'](message)
  File "C:\Telegram Bot\AccountBot\bot.py", line 1643, in handle_history_report
    msg += get_current_month_report_message()
           ^^^^^^^^^^^^^^^^^^^^^^^^^^^^^^^^
NameError: name 'get_current_month_report_message' is not defined

2025-05-05 15:54:26,308 - Ê©üÂô®‰∫∫Â∑≤ÂïüÂãï...
2025-05-05 15:54:27,630 - Threaded polling exception: A request to the Telegram API was unsuccessful. Error code: 409. Description: Conflict: terminated by other getUpdates request; make sure that only one bot instance is running
2025-05-05 15:54:27,631 - Exception traceback:
Traceback (most recent call last):
  File "C:\Users\Administrator\AppData\Local\Programs\Python\Python313\Lib\site-packages\telebot\__init__.py", line 1140, in __threaded_polling
    polling_thread.raise_exceptions()
    ~~~~~~~~~~~~~~~~~~~~~~~~~~~~~~~^^
  File "C:\Users\Administrator\AppData\Local\Programs\Python\Python313\Lib\site-packages\telebot\util.py", line 110, in raise_exceptions
    raise self.exception_info
  File "C:\Users\Administrator\AppData\Local\Programs\Python\Python313\Lib\site-packages\telebot\util.py", line 92, in run
    task(*args, **kwargs)
    ~~~~^^^^^^^^^^^^^^^^^
  File "C:\Users\Administrator\AppData\Local\Programs\Python\Python313\Lib\site-packages\telebot\__init__.py", line 661, in __retrieve_updates
    updates = self.get_updates(offset=(self.last_update_id + 1),
                               allowed_updates=allowed_updates,
                               timeout=timeout, long_polling_timeout=long_polling_timeout)
  File "C:\Users\Administrator\AppData\Local\Programs\Python\Python313\Lib\site-packages\telebot\__init__.py", line 633, in get_updates
    json_updates = apihelper.get_updates(
        self.token, offset=offset, limit=limit, timeout=timeout, allowed_updates=allowed_updates,
        long_polling_timeout=long_polling_timeout)
  File "C:\Users\Administrator\AppData\Local\Programs\Python\Python313\Lib\site-packages\telebot\apihelper.py", line 321, in get_updates
    return _make_request(token, method_url, params=payload)
  File "C:\Users\Administrator\AppData\Local\Programs\Python\Python313\Lib\site-packages\telebot\apihelper.py", line 164, in _make_request
    json_result = _check_result(method_name, result)
  File "C:\Users\Administrator\AppData\Local\Programs\Python\Python313\Lib\site-packages\telebot\apihelper.py", line 191, in _check_result
    raise ApiTelegramException(method_name, result, result_json)
telebot.apihelper.ApiTelegramException: A request to the Telegram API was unsuccessful. Error code: 409. Description: Conflict: terminated by other getUpdates request; make sure that only one bot instance is running

2025-05-05 15:54:31,101 - Threaded polling exception: A request to the Telegram API was unsuccessful. Error code: 409. Description: Conflict: terminated by other getUpdates request; make sure that only one bot instance is running
2025-05-05 15:54:31,104 - Exception traceback:
Traceback (most recent call last):
  File "C:\Users\Administrator\AppData\Local\Programs\Python\Python313\Lib\site-packages\telebot\__init__.py", line 1140, in __threaded_polling
    polling_thread.raise_exceptions()
    ~~~~~~~~~~~~~~~~~~~~~~~~~~~~~~~^^
  File "C:\Users\Administrator\AppData\Local\Programs\Python\Python313\Lib\site-packages\telebot\util.py", line 110, in raise_exceptions
    raise self.exception_info
  File "C:\Users\Administrator\AppData\Local\Programs\Python\Python313\Lib\site-packages\telebot\util.py", line 92, in run
    task(*args, **kwargs)
    ~~~~^^^^^^^^^^^^^^^^^
  File "C:\Users\Administrator\AppData\Local\Programs\Python\Python313\Lib\site-packages\telebot\__init__.py", line 661, in __retrieve_updates
    updates = self.get_updates(offset=(self.last_update_id + 1),
                               allowed_updates=allowed_updates,
                               timeout=timeout, long_polling_timeout=long_polling_timeout)
  File "C:\Users\Administrator\AppData\Local\Programs\Python\Python313\Lib\site-packages\telebot\__init__.py", line 633, in get_updates
    json_updates = apihelper.get_updates(
        self.token, offset=offset, limit=limit, timeout=timeout, allowed_updates=allowed_updates,
        long_polling_timeout=long_polling_timeout)
  File "C:\Users\Administrator\AppData\Local\Programs\Python\Python313\Lib\site-packages\telebot\apihelper.py", line 321, in get_updates
    return _make_request(token, method_url, params=payload)
  File "C:\Users\Administrator\AppData\Local\Programs\Python\Python313\Lib\site-packages\telebot\apihelper.py", line 164, in _make_request
    json_result = _check_result(method_name, result)
  File "C:\Users\Administrator\AppData\Local\Programs\Python\Python313\Lib\site-packages\telebot\apihelper.py", line 191, in _check_result
    raise ApiTelegramException(method_name, result, result_json)
telebot.apihelper.ApiTelegramException: A request to the Telegram API was unsuccessful. Error code: 409. Description: Conflict: terminated by other getUpdates request; make sure that only one bot instance is running

2025-05-05 15:54:31,583 - Threaded polling exception: A request to the Telegram API was unsuccessful. Error code: 409. Description: Conflict: terminated by other getUpdates request; make sure that only one bot instance is running
2025-05-05 15:54:31,585 - Exception traceback:
Traceback (most recent call last):
  File "C:\Users\Administrator\AppData\Local\Programs\Python\Python313\Lib\site-packages\telebot\__init__.py", line 1140, in __threaded_polling
    polling_thread.raise_exceptions()
    ~~~~~~~~~~~~~~~~~~~~~~~~~~~~~~~^^
  File "C:\Users\Administrator\AppData\Local\Programs\Python\Python313\Lib\site-packages\telebot\util.py", line 110, in raise_exceptions
    raise self.exception_info
  File "C:\Users\Administrator\AppData\Local\Programs\Python\Python313\Lib\site-packages\telebot\util.py", line 92, in run
    task(*args, **kwargs)
    ~~~~^^^^^^^^^^^^^^^^^
  File "C:\Users\Administrator\AppData\Local\Programs\Python\Python313\Lib\site-packages\telebot\__init__.py", line 661, in __retrieve_updates
    updates = self.get_updates(offset=(self.last_update_id + 1),
                               allowed_updates=allowed_updates,
                               timeout=timeout, long_polling_timeout=long_polling_timeout)
  File "C:\Users\Administrator\AppData\Local\Programs\Python\Python313\Lib\site-packages\telebot\__init__.py", line 633, in get_updates
    json_updates = apihelper.get_updates(
        self.token, offset=offset, limit=limit, timeout=timeout, allowed_updates=allowed_updates,
        long_polling_timeout=long_polling_timeout)
  File "C:\Users\Administrator\AppData\Local\Programs\Python\Python313\Lib\site-packages\telebot\apihelper.py", line 321, in get_updates
    return _make_request(token, method_url, params=payload)
  File "C:\Users\Administrator\AppData\Local\Programs\Python\Python313\Lib\site-packages\telebot\apihelper.py", line 164, in _make_request
    json_result = _check_result(method_name, result)
  File "C:\Users\Administrator\AppData\Local\Programs\Python\Python313\Lib\site-packages\telebot\apihelper.py", line 191, in _check_result
    raise ApiTelegramException(method_name, result, result_json)
telebot.apihelper.ApiTelegramException: A request to the Telegram API was unsuccessful. Error code: 409. Description: Conflict: terminated by other getUpdates request; make sure that only one bot instance is running

2025-05-05 15:54:35,307 - Threaded polling exception: A request to the Telegram API was unsuccessful. Error code: 409. Description: Conflict: terminated by other getUpdates request; make sure that only one bot instance is running
2025-05-05 15:54:35,310 - Exception traceback:
Traceback (most recent call last):
  File "C:\Users\Administrator\AppData\Local\Programs\Python\Python313\Lib\site-packages\telebot\__init__.py", line 1140, in __threaded_polling
    polling_thread.raise_exceptions()
    ~~~~~~~~~~~~~~~~~~~~~~~~~~~~~~~^^
  File "C:\Users\Administrator\AppData\Local\Programs\Python\Python313\Lib\site-packages\telebot\util.py", line 110, in raise_exceptions
    raise self.exception_info
  File "C:\Users\Administrator\AppData\Local\Programs\Python\Python313\Lib\site-packages\telebot\util.py", line 92, in run
    task(*args, **kwargs)
    ~~~~^^^^^^^^^^^^^^^^^
  File "C:\Users\Administrator\AppData\Local\Programs\Python\Python313\Lib\site-packages\telebot\__init__.py", line 661, in __retrieve_updates
    updates = self.get_updates(offset=(self.last_update_id + 1),
                               allowed_updates=allowed_updates,
                               timeout=timeout, long_polling_timeout=long_polling_timeout)
  File "C:\Users\Administrator\AppData\Local\Programs\Python\Python313\Lib\site-packages\telebot\__init__.py", line 633, in get_updates
    json_updates = apihelper.get_updates(
        self.token, offset=offset, limit=limit, timeout=timeout, allowed_updates=allowed_updates,
        long_polling_timeout=long_polling_timeout)
  File "C:\Users\Administrator\AppData\Local\Programs\Python\Python313\Lib\site-packages\telebot\apihelper.py", line 321, in get_updates
    return _make_request(token, method_url, params=payload)
  File "C:\Users\Administrator\AppData\Local\Programs\Python\Python313\Lib\site-packages\telebot\apihelper.py", line 164, in _make_request
    json_result = _check_result(method_name, result)
  File "C:\Users\Administrator\AppData\Local\Programs\Python\Python313\Lib\site-packages\telebot\apihelper.py", line 191, in _check_result
    raise ApiTelegramException(method_name, result, result_json)
telebot.apihelper.ApiTelegramException: A request to the Telegram API was unsuccessful. Error code: 409. Description: Conflict: terminated by other getUpdates request; make sure that only one bot instance is running

2025-05-05 15:54:36,027 - Threaded polling exception: A request to the Telegram API was unsuccessful. Error code: 409. Description: Conflict: terminated by other getUpdates request; make sure that only one bot instance is running
2025-05-05 15:54:36,029 - Exception traceback:
Traceback (most recent call last):
  File "C:\Users\Administrator\AppData\Local\Programs\Python\Python313\Lib\site-packages\telebot\__init__.py", line 1140, in __threaded_polling
    polling_thread.raise_exceptions()
    ~~~~~~~~~~~~~~~~~~~~~~~~~~~~~~~^^
  File "C:\Users\Administrator\AppData\Local\Programs\Python\Python313\Lib\site-packages\telebot\util.py", line 110, in raise_exceptions
    raise self.exception_info
  File "C:\Users\Administrator\AppData\Local\Programs\Python\Python313\Lib\site-packages\telebot\util.py", line 92, in run
    task(*args, **kwargs)
    ~~~~^^^^^^^^^^^^^^^^^
  File "C:\Users\Administrator\AppData\Local\Programs\Python\Python313\Lib\site-packages\telebot\__init__.py", line 661, in __retrieve_updates
    updates = self.get_updates(offset=(self.last_update_id + 1),
                               allowed_updates=allowed_updates,
                               timeout=timeout, long_polling_timeout=long_polling_timeout)
  File "C:\Users\Administrator\AppData\Local\Programs\Python\Python313\Lib\site-packages\telebot\__init__.py", line 633, in get_updates
    json_updates = apihelper.get_updates(
        self.token, offset=offset, limit=limit, timeout=timeout, allowed_updates=allowed_updates,
        long_polling_timeout=long_polling_timeout)
  File "C:\Users\Administrator\AppData\Local\Programs\Python\Python313\Lib\site-packages\telebot\apihelper.py", line 321, in get_updates
    return _make_request(token, method_url, params=payload)
  File "C:\Users\Administrator\AppData\Local\Programs\Python\Python313\Lib\site-packages\telebot\apihelper.py", line 164, in _make_request
    json_result = _check_result(method_name, result)
  File "C:\Users\Administrator\AppData\Local\Programs\Python\Python313\Lib\site-packages\telebot\apihelper.py", line 191, in _check_result
    raise ApiTelegramException(method_name, result, result_json)
telebot.apihelper.ApiTelegramException: A request to the Telegram API was unsuccessful. Error code: 409. Description: Conflict: terminated by other getUpdates request; make sure that only one bot instance is running

2025-05-05 15:54:40,056 - Infinity polling exception: KeyboardButton.__init__() got an unexpected keyword argument 'callback_data'
2025-05-05 15:54:40,059 - Exception traceback:
Traceback (most recent call last):
  File "C:\Users\Administrator\AppData\Local\Programs\Python\Python313\Lib\site-packages\telebot\__init__.py", line 1016, in infinity_polling
    self.polling(non_stop=True, timeout=timeout, long_polling_timeout=long_polling_timeout,
    ~~~~~~~~~~~~^^^^^^^^^^^^^^^^^^^^^^^^^^^^^^^^^^^^^^^^^^^^^^^^^^^^^^^^^^^^^^^^^^^^^^^^^^^
                 logger_level=logger_level, allowed_updates=allowed_updates, restart_on_change=False,
                 ^^^^^^^^^^^^^^^^^^^^^^^^^^^^^^^^^^^^^^^^^^^^^^^^^^^^^^^^^^^^^^^^^^^^^^^^^^^^^^^^^^^^
                 *args, **kwargs)
                 ^^^^^^^^^^^^^^^^
  File "C:\Users\Administrator\AppData\Local\Programs\Python\Python313\Lib\site-packages\telebot\__init__.py", line 1104, in polling
    self.__threaded_polling(non_stop=non_stop, interval=interval, timeout=timeout, long_polling_timeout=long_polling_timeout,
    ~~~~~~~~~~~~~~~~~~~~~~~^^^^^^^^^^^^^^^^^^^^^^^^^^^^^^^^^^^^^^^^^^^^^^^^^^^^^^^^^^^^^^^^^^^^^^^^^^^^^^^^^^^^^^^^^^^^^^^^^^
                            logger_level=logger_level, allowed_updates=allowed_updates)
                            ^^^^^^^^^^^^^^^^^^^^^^^^^^^^^^^^^^^^^^^^^^^^^^^^^^^^^^^^^^^
  File "C:\Users\Administrator\AppData\Local\Programs\Python\Python313\Lib\site-packages\telebot\__init__.py", line 1179, in __threaded_polling
    raise e
  File "C:\Users\Administrator\AppData\Local\Programs\Python\Python313\Lib\site-packages\telebot\__init__.py", line 1141, in __threaded_polling
    self.worker_pool.raise_exceptions()
    ~~~~~~~~~~~~~~~~~~~~~~~~~~~~~~~~~^^
  File "C:\Users\Administrator\AppData\Local\Programs\Python\Python313\Lib\site-packages\telebot\util.py", line 149, in raise_exceptions
    raise self.exception_info
  File "C:\Users\Administrator\AppData\Local\Programs\Python\Python313\Lib\site-packages\telebot\util.py", line 92, in run
    task(*args, **kwargs)
    ~~~~^^^^^^^^^^^^^^^^^
  File "C:\Users\Administrator\AppData\Local\Programs\Python\Python313\Lib\site-packages\telebot\__init__.py", line 7860, in _run_middlewares_and_handler
    result = handler['function'](message)
  File "C:\Telegram Bot\AccountBot\bot.py", line 1840, in handle_change_notify_toggle
    bot.reply_to(message, f'Áï∞ÂãïÊèêÈÜí{status}', reply_markup=create_main_menu())
                                                            ~~~~~~~~~~~~~~~~^^
  File "C:\Telegram Bot\AccountBot\bot.py", line 114, in create_main_menu
    KeyboardButton('üîÑÔ∏èÈáçÊñ∞ÂïüÂãï', callback_data=None)  # ÊåâÈàïÂêçÁ®±ÊîπÁÇ∫„ÄéüîÑÔ∏èÈáçÊñ∞ÂïüÂãï„Äè
    ~~~~~~~~~~~~~~^^^^^^^^^^^^^^^^^^^^^^^^^^^^^^^^^^^
TypeError: KeyboardButton.__init__() got an unexpected keyword argument 'callback_data'

2025-05-05 15:54:40,248 - Threaded polling exception: A request to the Telegram API was unsuccessful. Error code: 409. Description: Conflict: terminated by other getUpdates request; make sure that only one bot instance is running
2025-05-05 15:54:40,252 - Exception traceback:
Traceback (most recent call last):
  File "C:\Users\Administrator\AppData\Local\Programs\Python\Python313\Lib\site-packages\telebot\__init__.py", line 1140, in __threaded_polling
    polling_thread.raise_exceptions()
    ~~~~~~~~~~~~~~~~~~~~~~~~~~~~~~~^^
  File "C:\Users\Administrator\AppData\Local\Programs\Python\Python313\Lib\site-packages\telebot\util.py", line 110, in raise_exceptions
    raise self.exception_info
  File "C:\Users\Administrator\AppData\Local\Programs\Python\Python313\Lib\site-packages\telebot\util.py", line 92, in run
    task(*args, **kwargs)
    ~~~~^^^^^^^^^^^^^^^^^
  File "C:\Users\Administrator\AppData\Local\Programs\Python\Python313\Lib\site-packages\telebot\__init__.py", line 661, in __retrieve_updates
    updates = self.get_updates(offset=(self.last_update_id + 1),
                               allowed_updates=allowed_updates,
                               timeout=timeout, long_polling_timeout=long_polling_timeout)
  File "C:\Users\Administrator\AppData\Local\Programs\Python\Python313\Lib\site-packages\telebot\__init__.py", line 633, in get_updates
    json_updates = apihelper.get_updates(
        self.token, offset=offset, limit=limit, timeout=timeout, allowed_updates=allowed_updates,
        long_polling_timeout=long_polling_timeout)
  File "C:\Users\Administrator\AppData\Local\Programs\Python\Python313\Lib\site-packages\telebot\apihelper.py", line 321, in get_updates
    return _make_request(token, method_url, params=payload)
  File "C:\Users\Administrator\AppData\Local\Programs\Python\Python313\Lib\site-packages\telebot\apihelper.py", line 164, in _make_request
    json_result = _check_result(method_name, result)
  File "C:\Users\Administrator\AppData\Local\Programs\Python\Python313\Lib\site-packages\telebot\apihelper.py", line 191, in _check_result
    raise ApiTelegramException(method_name, result, result_json)
telebot.apihelper.ApiTelegramException: A request to the Telegram API was unsuccessful. Error code: 409. Description: Conflict: terminated by other getUpdates request; make sure that only one bot instance is running

2025-05-05 15:54:41,477 - Infinity polling exception: KeyboardButton.__init__() got an unexpected keyword argument 'callback_data'
2025-05-05 15:54:41,482 - Exception traceback:
Traceback (most recent call last):
  File "C:\Users\Administrator\AppData\Local\Programs\Python\Python313\Lib\site-packages\telebot\__init__.py", line 1016, in infinity_polling
    self.polling(non_stop=True, timeout=timeout, long_polling_timeout=long_polling_timeout,
    ~~~~~~~~~~~~^^^^^^^^^^^^^^^^^^^^^^^^^^^^^^^^^^^^^^^^^^^^^^^^^^^^^^^^^^^^^^^^^^^^^^^^^^^
                 logger_level=logger_level, allowed_updates=allowed_updates, restart_on_change=False,
                 ^^^^^^^^^^^^^^^^^^^^^^^^^^^^^^^^^^^^^^^^^^^^^^^^^^^^^^^^^^^^^^^^^^^^^^^^^^^^^^^^^^^^
                 *args, **kwargs)
                 ^^^^^^^^^^^^^^^^
  File "C:\Users\Administrator\AppData\Local\Programs\Python\Python313\Lib\site-packages\telebot\__init__.py", line 1104, in polling
    self.__threaded_polling(non_stop=non_stop, interval=interval, timeout=timeout, long_polling_timeout=long_polling_timeout,
    ~~~~~~~~~~~~~~~~~~~~~~~^^^^^^^^^^^^^^^^^^^^^^^^^^^^^^^^^^^^^^^^^^^^^^^^^^^^^^^^^^^^^^^^^^^^^^^^^^^^^^^^^^^^^^^^^^^^^^^^^^
                            logger_level=logger_level, allowed_updates=allowed_updates)
                            ^^^^^^^^^^^^^^^^^^^^^^^^^^^^^^^^^^^^^^^^^^^^^^^^^^^^^^^^^^^
  File "C:\Users\Administrator\AppData\Local\Programs\Python\Python313\Lib\site-packages\telebot\__init__.py", line 1179, in __threaded_polling
    raise e
  File "C:\Users\Administrator\AppData\Local\Programs\Python\Python313\Lib\site-packages\telebot\__init__.py", line 1141, in __threaded_polling
    self.worker_pool.raise_exceptions()
    ~~~~~~~~~~~~~~~~~~~~~~~~~~~~~~~~~^^
  File "C:\Users\Administrator\AppData\Local\Programs\Python\Python313\Lib\site-packages\telebot\util.py", line 149, in raise_exceptions
    raise self.exception_info
  File "C:\Users\Administrator\AppData\Local\Programs\Python\Python313\Lib\site-packages\telebot\util.py", line 92, in run
    task(*args, **kwargs)
    ~~~~^^^^^^^^^^^^^^^^^
  File "C:\Users\Administrator\AppData\Local\Programs\Python\Python313\Lib\site-packages\telebot\__init__.py", line 7860, in _run_middlewares_and_handler
    result = handler['function'](message)
  File "C:\Telegram Bot\AccountBot\bot.py", line 1840, in handle_change_notify_toggle
    bot.reply_to(message, f'Áï∞ÂãïÊèêÈÜí{status}', reply_markup=create_main_menu())
                                                            ~~~~~~~~~~~~~~~~^^
  File "C:\Telegram Bot\AccountBot\bot.py", line 114, in create_main_menu
    KeyboardButton('üîÑÔ∏èÈáçÊñ∞ÂïüÂãï', callback_data=None)  # ÊåâÈàïÂêçÁ®±ÊîπÁÇ∫„ÄéüîÑÔ∏èÈáçÊñ∞ÂïüÂãï„Äè
    ~~~~~~~~~~~~~~^^^^^^^^^^^^^^^^^^^^^^^^^^^^^^^^^^^
TypeError: KeyboardButton.__init__() got an unexpected keyword argument 'callback_data'

2025-05-05 15:54:43,062 - Infinity polling exception: KeyboardButton.__init__() got an unexpected keyword argument 'callback_data'
2025-05-05 15:54:43,068 - Exception traceback:
Traceback (most recent call last):
  File "C:\Users\Administrator\AppData\Local\Programs\Python\Python313\Lib\site-packages\telebot\__init__.py", line 1016, in infinity_polling
    self.polling(non_stop=True, timeout=timeout, long_polling_timeout=long_polling_timeout,
    ~~~~~~~~~~~~^^^^^^^^^^^^^^^^^^^^^^^^^^^^^^^^^^^^^^^^^^^^^^^^^^^^^^^^^^^^^^^^^^^^^^^^^^^
                 logger_level=logger_level, allowed_updates=allowed_updates, restart_on_change=False,
                 ^^^^^^^^^^^^^^^^^^^^^^^^^^^^^^^^^^^^^^^^^^^^^^^^^^^^^^^^^^^^^^^^^^^^^^^^^^^^^^^^^^^^
                 *args, **kwargs)
                 ^^^^^^^^^^^^^^^^
  File "C:\Users\Administrator\AppData\Local\Programs\Python\Python313\Lib\site-packages\telebot\__init__.py", line 1104, in polling
    self.__threaded_polling(non_stop=non_stop, interval=interval, timeout=timeout, long_polling_timeout=long_polling_timeout,
    ~~~~~~~~~~~~~~~~~~~~~~~^^^^^^^^^^^^^^^^^^^^^^^^^^^^^^^^^^^^^^^^^^^^^^^^^^^^^^^^^^^^^^^^^^^^^^^^^^^^^^^^^^^^^^^^^^^^^^^^^^
                            logger_level=logger_level, allowed_updates=allowed_updates)
                            ^^^^^^^^^^^^^^^^^^^^^^^^^^^^^^^^^^^^^^^^^^^^^^^^^^^^^^^^^^^
  File "C:\Users\Administrator\AppData\Local\Programs\Python\Python313\Lib\site-packages\telebot\__init__.py", line 1179, in __threaded_polling
    raise e
  File "C:\Users\Administrator\AppData\Local\Programs\Python\Python313\Lib\site-packages\telebot\__init__.py", line 1141, in __threaded_polling
    self.worker_pool.raise_exceptions()
    ~~~~~~~~~~~~~~~~~~~~~~~~~~~~~~~~~^^
  File "C:\Users\Administrator\AppData\Local\Programs\Python\Python313\Lib\site-packages\telebot\util.py", line 149, in raise_exceptions
    raise self.exception_info
  File "C:\Users\Administrator\AppData\Local\Programs\Python\Python313\Lib\site-packages\telebot\util.py", line 92, in run
    task(*args, **kwargs)
    ~~~~^^^^^^^^^^^^^^^^^
  File "C:\Users\Administrator\AppData\Local\Programs\Python\Python313\Lib\site-packages\telebot\__init__.py", line 7860, in _run_middlewares_and_handler
    result = handler['function'](message)
  File "C:\Telegram Bot\AccountBot\bot.py", line 1840, in handle_change_notify_toggle
    bot.reply_to(message, f'Áï∞ÂãïÊèêÈÜí{status}', reply_markup=create_main_menu())
                                                            ~~~~~~~~~~~~~~~~^^
  File "C:\Telegram Bot\AccountBot\bot.py", line 114, in create_main_menu
    KeyboardButton('üîÑÔ∏èÈáçÊñ∞ÂïüÂãï', callback_data=None)  # ÊåâÈàïÂêçÁ®±ÊîπÁÇ∫„ÄéüîÑÔ∏èÈáçÊñ∞ÂïüÂãï„Äè
    ~~~~~~~~~~~~~~^^^^^^^^^^^^^^^^^^^^^^^^^^^^^^^^^^^
TypeError: KeyboardButton.__init__() got an unexpected keyword argument 'callback_data'

2025-05-05 15:54:45,139 - Infinity polling exception: KeyboardButton.__init__() got an unexpected keyword argument 'callback_data'
2025-05-05 15:54:45,142 - Exception traceback:
Traceback (most recent call last):
  File "C:\Users\Administrator\AppData\Local\Programs\Python\Python313\Lib\site-packages\telebot\__init__.py", line 1016, in infinity_polling
    self.polling(non_stop=True, timeout=timeout, long_polling_timeout=long_polling_timeout,
    ~~~~~~~~~~~~^^^^^^^^^^^^^^^^^^^^^^^^^^^^^^^^^^^^^^^^^^^^^^^^^^^^^^^^^^^^^^^^^^^^^^^^^^^
                 logger_level=logger_level, allowed_updates=allowed_updates, restart_on_change=False,
                 ^^^^^^^^^^^^^^^^^^^^^^^^^^^^^^^^^^^^^^^^^^^^^^^^^^^^^^^^^^^^^^^^^^^^^^^^^^^^^^^^^^^^
                 *args, **kwargs)
                 ^^^^^^^^^^^^^^^^
  File "C:\Users\Administrator\AppData\Local\Programs\Python\Python313\Lib\site-packages\telebot\__init__.py", line 1104, in polling
    self.__threaded_polling(non_stop=non_stop, interval=interval, timeout=timeout, long_polling_timeout=long_polling_timeout,
    ~~~~~~~~~~~~~~~~~~~~~~~^^^^^^^^^^^^^^^^^^^^^^^^^^^^^^^^^^^^^^^^^^^^^^^^^^^^^^^^^^^^^^^^^^^^^^^^^^^^^^^^^^^^^^^^^^^^^^^^^^
                            logger_level=logger_level, allowed_updates=allowed_updates)
                            ^^^^^^^^^^^^^^^^^^^^^^^^^^^^^^^^^^^^^^^^^^^^^^^^^^^^^^^^^^^
  File "C:\Users\Administrator\AppData\Local\Programs\Python\Python313\Lib\site-packages\telebot\__init__.py", line 1179, in __threaded_polling
    raise e
  File "C:\Users\Administrator\AppData\Local\Programs\Python\Python313\Lib\site-packages\telebot\__init__.py", line 1141, in __threaded_polling
    self.worker_pool.raise_exceptions()
    ~~~~~~~~~~~~~~~~~~~~~~~~~~~~~~~~~^^
  File "C:\Users\Administrator\AppData\Local\Programs\Python\Python313\Lib\site-packages\telebot\util.py", line 149, in raise_exceptions
    raise self.exception_info
  File "C:\Users\Administrator\AppData\Local\Programs\Python\Python313\Lib\site-packages\telebot\util.py", line 92, in run
    task(*args, **kwargs)
    ~~~~^^^^^^^^^^^^^^^^^
  File "C:\Users\Administrator\AppData\Local\Programs\Python\Python313\Lib\site-packages\telebot\__init__.py", line 7860, in _run_middlewares_and_handler
    result = handler['function'](message)
  File "C:\Telegram Bot\AccountBot\bot.py", line 1840, in handle_change_notify_toggle
    bot.reply_to(message, f'Áï∞ÂãïÊèêÈÜí{status}', reply_markup=create_main_menu())
                                                            ~~~~~~~~~~~~~~~~^^
  File "C:\Telegram Bot\AccountBot\bot.py", line 114, in create_main_menu
    KeyboardButton('üîÑÔ∏èÈáçÊñ∞ÂïüÂãï', callback_data=None)  # ÊåâÈàïÂêçÁ®±ÊîπÁÇ∫„ÄéüîÑÔ∏èÈáçÊñ∞ÂïüÂãï„Äè
    ~~~~~~~~~~~~~~^^^^^^^^^^^^^^^^^^^^^^^^^^^^^^^^^^^
TypeError: KeyboardButton.__init__() got an unexpected keyword argument 'callback_data'

2025-05-05 15:54:46,070 - Infinity polling exception: KeyboardButton.__init__() got an unexpected keyword argument 'callback_data'
2025-05-05 15:54:46,073 - Exception traceback:
Traceback (most recent call last):
  File "C:\Users\Administrator\AppData\Local\Programs\Python\Python313\Lib\site-packages\telebot\__init__.py", line 1016, in infinity_polling
    self.polling(non_stop=True, timeout=timeout, long_polling_timeout=long_polling_timeout,
    ~~~~~~~~~~~~^^^^^^^^^^^^^^^^^^^^^^^^^^^^^^^^^^^^^^^^^^^^^^^^^^^^^^^^^^^^^^^^^^^^^^^^^^^
                 logger_level=logger_level, allowed_updates=allowed_updates, restart_on_change=False,
                 ^^^^^^^^^^^^^^^^^^^^^^^^^^^^^^^^^^^^^^^^^^^^^^^^^^^^^^^^^^^^^^^^^^^^^^^^^^^^^^^^^^^^
                 *args, **kwargs)
                 ^^^^^^^^^^^^^^^^
  File "C:\Users\Administrator\AppData\Local\Programs\Python\Python313\Lib\site-packages\telebot\__init__.py", line 1104, in polling
    self.__threaded_polling(non_stop=non_stop, interval=interval, timeout=timeout, long_polling_timeout=long_polling_timeout,
    ~~~~~~~~~~~~~~~~~~~~~~~^^^^^^^^^^^^^^^^^^^^^^^^^^^^^^^^^^^^^^^^^^^^^^^^^^^^^^^^^^^^^^^^^^^^^^^^^^^^^^^^^^^^^^^^^^^^^^^^^^
                            logger_level=logger_level, allowed_updates=allowed_updates)
                            ^^^^^^^^^^^^^^^^^^^^^^^^^^^^^^^^^^^^^^^^^^^^^^^^^^^^^^^^^^^
  File "C:\Users\Administrator\AppData\Local\Programs\Python\Python313\Lib\site-packages\telebot\__init__.py", line 1179, in __threaded_polling
    raise e
  File "C:\Users\Administrator\AppData\Local\Programs\Python\Python313\Lib\site-packages\telebot\__init__.py", line 1141, in __threaded_polling
    self.worker_pool.raise_exceptions()
    ~~~~~~~~~~~~~~~~~~~~~~~~~~~~~~~~~^^
  File "C:\Users\Administrator\AppData\Local\Programs\Python\Python313\Lib\site-packages\telebot\util.py", line 149, in raise_exceptions
    raise self.exception_info
  File "C:\Users\Administrator\AppData\Local\Programs\Python\Python313\Lib\site-packages\telebot\util.py", line 92, in run
    task(*args, **kwargs)
    ~~~~^^^^^^^^^^^^^^^^^
  File "C:\Users\Administrator\AppData\Local\Programs\Python\Python313\Lib\site-packages\telebot\__init__.py", line 7860, in _run_middlewares_and_handler
    result = handler['function'](message)
  File "C:\Telegram Bot\AccountBot\bot.py", line 1840, in handle_change_notify_toggle
    bot.reply_to(message, f'Áï∞ÂãïÊèêÈÜí{status}', reply_markup=create_main_menu())
                                                            ~~~~~~~~~~~~~~~~^^
  File "C:\Telegram Bot\AccountBot\bot.py", line 114, in create_main_menu
    KeyboardButton('üîÑÔ∏èÈáçÊñ∞ÂïüÂãï', callback_data=None)  # ÊåâÈàïÂêçÁ®±ÊîπÁÇ∫„ÄéüîÑÔ∏èÈáçÊñ∞ÂïüÂãï„Äè
    ~~~~~~~~~~~~~~^^^^^^^^^^^^^^^^^^^^^^^^^^^^^^^^^^^
TypeError: KeyboardButton.__init__() got an unexpected keyword argument 'callback_data'

2025-05-05 15:54:52,725 - Threaded polling exception: A request to the Telegram API was unsuccessful. Error code: 409. Description: Conflict: terminated by other getUpdates request; make sure that only one bot instance is running
2025-05-05 15:54:52,727 - Exception traceback:
Traceback (most recent call last):
  File "C:\Users\Administrator\AppData\Local\Programs\Python\Python313\Lib\site-packages\telebot\__init__.py", line 1140, in __threaded_polling
    polling_thread.raise_exceptions()
    ~~~~~~~~~~~~~~~~~~~~~~~~~~~~~~~^^
  File "C:\Users\Administrator\AppData\Local\Programs\Python\Python313\Lib\site-packages\telebot\util.py", line 110, in raise_exceptions
    raise self.exception_info
  File "C:\Users\Administrator\AppData\Local\Programs\Python\Python313\Lib\site-packages\telebot\util.py", line 92, in run
    task(*args, **kwargs)
    ~~~~^^^^^^^^^^^^^^^^^
  File "C:\Users\Administrator\AppData\Local\Programs\Python\Python313\Lib\site-packages\telebot\__init__.py", line 661, in __retrieve_updates
    updates = self.get_updates(offset=(self.last_update_id + 1),
                               allowed_updates=allowed_updates,
                               timeout=timeout, long_polling_timeout=long_polling_timeout)
  File "C:\Users\Administrator\AppData\Local\Programs\Python\Python313\Lib\site-packages\telebot\__init__.py", line 633, in get_updates
    json_updates = apihelper.get_updates(
        self.token, offset=offset, limit=limit, timeout=timeout, allowed_updates=allowed_updates,
        long_polling_timeout=long_polling_timeout)
  File "C:\Users\Administrator\AppData\Local\Programs\Python\Python313\Lib\site-packages\telebot\apihelper.py", line 321, in get_updates
    return _make_request(token, method_url, params=payload)
  File "C:\Users\Administrator\AppData\Local\Programs\Python\Python313\Lib\site-packages\telebot\apihelper.py", line 164, in _make_request
    json_result = _check_result(method_name, result)
  File "C:\Users\Administrator\AppData\Local\Programs\Python\Python313\Lib\site-packages\telebot\apihelper.py", line 191, in _check_result
    raise ApiTelegramException(method_name, result, result_json)
telebot.apihelper.ApiTelegramException: A request to the Telegram API was unsuccessful. Error code: 409. Description: Conflict: terminated by other getUpdates request; make sure that only one bot instance is running

2025-05-05 15:54:53,196 - Threaded polling exception: A request to the Telegram API was unsuccessful. Error code: 409. Description: Conflict: terminated by other getUpdates request; make sure that only one bot instance is running
2025-05-05 15:54:53,199 - Exception traceback:
Traceback (most recent call last):
  File "C:\Users\Administrator\AppData\Local\Programs\Python\Python313\Lib\site-packages\telebot\__init__.py", line 1140, in __threaded_polling
    polling_thread.raise_exceptions()
    ~~~~~~~~~~~~~~~~~~~~~~~~~~~~~~~^^
  File "C:\Users\Administrator\AppData\Local\Programs\Python\Python313\Lib\site-packages\telebot\util.py", line 110, in raise_exceptions
    raise self.exception_info
  File "C:\Users\Administrator\AppData\Local\Programs\Python\Python313\Lib\site-packages\telebot\util.py", line 92, in run
    task(*args, **kwargs)
    ~~~~^^^^^^^^^^^^^^^^^
  File "C:\Users\Administrator\AppData\Local\Programs\Python\Python313\Lib\site-packages\telebot\__init__.py", line 661, in __retrieve_updates
    updates = self.get_updates(offset=(self.last_update_id + 1),
                               allowed_updates=allowed_updates,
                               timeout=timeout, long_polling_timeout=long_polling_timeout)
  File "C:\Users\Administrator\AppData\Local\Programs\Python\Python313\Lib\site-packages\telebot\__init__.py", line 633, in get_updates
    json_updates = apihelper.get_updates(
        self.token, offset=offset, limit=limit, timeout=timeout, allowed_updates=allowed_updates,
        long_polling_timeout=long_polling_timeout)
  File "C:\Users\Administrator\AppData\Local\Programs\Python\Python313\Lib\site-packages\telebot\apihelper.py", line 321, in get_updates
    return _make_request(token, method_url, params=payload)
  File "C:\Users\Administrator\AppData\Local\Programs\Python\Python313\Lib\site-packages\telebot\apihelper.py", line 164, in _make_request
    json_result = _check_result(method_name, result)
  File "C:\Users\Administrator\AppData\Local\Programs\Python\Python313\Lib\site-packages\telebot\apihelper.py", line 191, in _check_result
    raise ApiTelegramException(method_name, result, result_json)
telebot.apihelper.ApiTelegramException: A request to the Telegram API was unsuccessful. Error code: 409. Description: Conflict: terminated by other getUpdates request; make sure that only one bot instance is running

2025-05-05 15:54:56,670 - Threaded polling exception: A request to the Telegram API was unsuccessful. Error code: 409. Description: Conflict: terminated by other getUpdates request; make sure that only one bot instance is running
2025-05-05 15:54:56,672 - Exception traceback:
Traceback (most recent call last):
  File "C:\Users\Administrator\AppData\Local\Programs\Python\Python313\Lib\site-packages\telebot\__init__.py", line 1140, in __threaded_polling
    polling_thread.raise_exceptions()
    ~~~~~~~~~~~~~~~~~~~~~~~~~~~~~~~^^
  File "C:\Users\Administrator\AppData\Local\Programs\Python\Python313\Lib\site-packages\telebot\util.py", line 110, in raise_exceptions
    raise self.exception_info
  File "C:\Users\Administrator\AppData\Local\Programs\Python\Python313\Lib\site-packages\telebot\util.py", line 92, in run
    task(*args, **kwargs)
    ~~~~^^^^^^^^^^^^^^^^^
  File "C:\Users\Administrator\AppData\Local\Programs\Python\Python313\Lib\site-packages\telebot\__init__.py", line 661, in __retrieve_updates
    updates = self.get_updates(offset=(self.last_update_id + 1),
                               allowed_updates=allowed_updates,
                               timeout=timeout, long_polling_timeout=long_polling_timeout)
  File "C:\Users\Administrator\AppData\Local\Programs\Python\Python313\Lib\site-packages\telebot\__init__.py", line 633, in get_updates
    json_updates = apihelper.get_updates(
        self.token, offset=offset, limit=limit, timeout=timeout, allowed_updates=allowed_updates,
        long_polling_timeout=long_polling_timeout)
  File "C:\Users\Administrator\AppData\Local\Programs\Python\Python313\Lib\site-packages\telebot\apihelper.py", line 321, in get_updates
    return _make_request(token, method_url, params=payload)
  File "C:\Users\Administrator\AppData\Local\Programs\Python\Python313\Lib\site-packages\telebot\apihelper.py", line 164, in _make_request
    json_result = _check_result(method_name, result)
  File "C:\Users\Administrator\AppData\Local\Programs\Python\Python313\Lib\site-packages\telebot\apihelper.py", line 191, in _check_result
    raise ApiTelegramException(method_name, result, result_json)
telebot.apihelper.ApiTelegramException: A request to the Telegram API was unsuccessful. Error code: 409. Description: Conflict: terminated by other getUpdates request; make sure that only one bot instance is running

2025-05-05 15:54:57,391 - Threaded polling exception: A request to the Telegram API was unsuccessful. Error code: 409. Description: Conflict: terminated by other getUpdates request; make sure that only one bot instance is running
2025-05-05 15:54:57,393 - Exception traceback:
Traceback (most recent call last):
  File "C:\Users\Administrator\AppData\Local\Programs\Python\Python313\Lib\site-packages\telebot\__init__.py", line 1140, in __threaded_polling
    polling_thread.raise_exceptions()
    ~~~~~~~~~~~~~~~~~~~~~~~~~~~~~~~^^
  File "C:\Users\Administrator\AppData\Local\Programs\Python\Python313\Lib\site-packages\telebot\util.py", line 110, in raise_exceptions
    raise self.exception_info
  File "C:\Users\Administrator\AppData\Local\Programs\Python\Python313\Lib\site-packages\telebot\util.py", line 92, in run
    task(*args, **kwargs)
    ~~~~^^^^^^^^^^^^^^^^^
  File "C:\Users\Administrator\AppData\Local\Programs\Python\Python313\Lib\site-packages\telebot\__init__.py", line 661, in __retrieve_updates
    updates = self.get_updates(offset=(self.last_update_id + 1),
                               allowed_updates=allowed_updates,
                               timeout=timeout, long_polling_timeout=long_polling_timeout)
  File "C:\Users\Administrator\AppData\Local\Programs\Python\Python313\Lib\site-packages\telebot\__init__.py", line 633, in get_updates
    json_updates = apihelper.get_updates(
        self.token, offset=offset, limit=limit, timeout=timeout, allowed_updates=allowed_updates,
        long_polling_timeout=long_polling_timeout)
  File "C:\Users\Administrator\AppData\Local\Programs\Python\Python313\Lib\site-packages\telebot\apihelper.py", line 321, in get_updates
    return _make_request(token, method_url, params=payload)
  File "C:\Users\Administrator\AppData\Local\Programs\Python\Python313\Lib\site-packages\telebot\apihelper.py", line 164, in _make_request
    json_result = _check_result(method_name, result)
  File "C:\Users\Administrator\AppData\Local\Programs\Python\Python313\Lib\site-packages\telebot\apihelper.py", line 191, in _check_result
    raise ApiTelegramException(method_name, result, result_json)
telebot.apihelper.ApiTelegramException: A request to the Telegram API was unsuccessful. Error code: 409. Description: Conflict: terminated by other getUpdates request; make sure that only one bot instance is running

2025-05-05 15:55:01,118 - Threaded polling exception: A request to the Telegram API was unsuccessful. Error code: 409. Description: Conflict: terminated by other getUpdates request; make sure that only one bot instance is running
2025-05-05 15:55:01,120 - Exception traceback:
Traceback (most recent call last):
  File "C:\Users\Administrator\AppData\Local\Programs\Python\Python313\Lib\site-packages\telebot\__init__.py", line 1140, in __threaded_polling
    polling_thread.raise_exceptions()
    ~~~~~~~~~~~~~~~~~~~~~~~~~~~~~~~^^
  File "C:\Users\Administrator\AppData\Local\Programs\Python\Python313\Lib\site-packages\telebot\util.py", line 110, in raise_exceptions
    raise self.exception_info
  File "C:\Users\Administrator\AppData\Local\Programs\Python\Python313\Lib\site-packages\telebot\util.py", line 92, in run
    task(*args, **kwargs)
    ~~~~^^^^^^^^^^^^^^^^^
  File "C:\Users\Administrator\AppData\Local\Programs\Python\Python313\Lib\site-packages\telebot\__init__.py", line 661, in __retrieve_updates
    updates = self.get_updates(offset=(self.last_update_id + 1),
                               allowed_updates=allowed_updates,
                               timeout=timeout, long_polling_timeout=long_polling_timeout)
  File "C:\Users\Administrator\AppData\Local\Programs\Python\Python313\Lib\site-packages\telebot\__init__.py", line 633, in get_updates
    json_updates = apihelper.get_updates(
        self.token, offset=offset, limit=limit, timeout=timeout, allowed_updates=allowed_updates,
        long_polling_timeout=long_polling_timeout)
  File "C:\Users\Administrator\AppData\Local\Programs\Python\Python313\Lib\site-packages\telebot\apihelper.py", line 321, in get_updates
    return _make_request(token, method_url, params=payload)
  File "C:\Users\Administrator\AppData\Local\Programs\Python\Python313\Lib\site-packages\telebot\apihelper.py", line 164, in _make_request
    json_result = _check_result(method_name, result)
  File "C:\Users\Administrator\AppData\Local\Programs\Python\Python313\Lib\site-packages\telebot\apihelper.py", line 191, in _check_result
    raise ApiTelegramException(method_name, result, result_json)
telebot.apihelper.ApiTelegramException: A request to the Telegram API was unsuccessful. Error code: 409. Description: Conflict: terminated by other getUpdates request; make sure that only one bot instance is running

2025-05-05 15:55:02,350 - Threaded polling exception: A request to the Telegram API was unsuccessful. Error code: 409. Description: Conflict: terminated by other getUpdates request; make sure that only one bot instance is running
2025-05-05 15:55:02,352 - Exception traceback:
Traceback (most recent call last):
  File "C:\Users\Administrator\AppData\Local\Programs\Python\Python313\Lib\site-packages\telebot\__init__.py", line 1140, in __threaded_polling
    polling_thread.raise_exceptions()
    ~~~~~~~~~~~~~~~~~~~~~~~~~~~~~~~^^
  File "C:\Users\Administrator\AppData\Local\Programs\Python\Python313\Lib\site-packages\telebot\util.py", line 110, in raise_exceptions
    raise self.exception_info
  File "C:\Users\Administrator\AppData\Local\Programs\Python\Python313\Lib\site-packages\telebot\util.py", line 92, in run
    task(*args, **kwargs)
    ~~~~^^^^^^^^^^^^^^^^^
  File "C:\Users\Administrator\AppData\Local\Programs\Python\Python313\Lib\site-packages\telebot\__init__.py", line 661, in __retrieve_updates
    updates = self.get_updates(offset=(self.last_update_id + 1),
                               allowed_updates=allowed_updates,
                               timeout=timeout, long_polling_timeout=long_polling_timeout)
  File "C:\Users\Administrator\AppData\Local\Programs\Python\Python313\Lib\site-packages\telebot\__init__.py", line 633, in get_updates
    json_updates = apihelper.get_updates(
        self.token, offset=offset, limit=limit, timeout=timeout, allowed_updates=allowed_updates,
        long_polling_timeout=long_polling_timeout)
  File "C:\Users\Administrator\AppData\Local\Programs\Python\Python313\Lib\site-packages\telebot\apihelper.py", line 321, in get_updates
    return _make_request(token, method_url, params=payload)
  File "C:\Users\Administrator\AppData\Local\Programs\Python\Python313\Lib\site-packages\telebot\apihelper.py", line 164, in _make_request
    json_result = _check_result(method_name, result)
  File "C:\Users\Administrator\AppData\Local\Programs\Python\Python313\Lib\site-packages\telebot\apihelper.py", line 191, in _check_result
    raise ApiTelegramException(method_name, result, result_json)
telebot.apihelper.ApiTelegramException: A request to the Telegram API was unsuccessful. Error code: 409. Description: Conflict: terminated by other getUpdates request; make sure that only one bot instance is running

2025-05-05 15:55:06,582 - Threaded polling exception: A request to the Telegram API was unsuccessful. Error code: 409. Description: Conflict: terminated by other getUpdates request; make sure that only one bot instance is running
2025-05-05 15:55:06,584 - Exception traceback:
Traceback (most recent call last):
  File "C:\Users\Administrator\AppData\Local\Programs\Python\Python313\Lib\site-packages\telebot\__init__.py", line 1140, in __threaded_polling
    polling_thread.raise_exceptions()
    ~~~~~~~~~~~~~~~~~~~~~~~~~~~~~~~^^
  File "C:\Users\Administrator\AppData\Local\Programs\Python\Python313\Lib\site-packages\telebot\util.py", line 110, in raise_exceptions
    raise self.exception_info
  File "C:\Users\Administrator\AppData\Local\Programs\Python\Python313\Lib\site-packages\telebot\util.py", line 92, in run
    task(*args, **kwargs)
    ~~~~^^^^^^^^^^^^^^^^^
  File "C:\Users\Administrator\AppData\Local\Programs\Python\Python313\Lib\site-packages\telebot\__init__.py", line 661, in __retrieve_updates
    updates = self.get_updates(offset=(self.last_update_id + 1),
                               allowed_updates=allowed_updates,
                               timeout=timeout, long_polling_timeout=long_polling_timeout)
  File "C:\Users\Administrator\AppData\Local\Programs\Python\Python313\Lib\site-packages\telebot\__init__.py", line 633, in get_updates
    json_updates = apihelper.get_updates(
        self.token, offset=offset, limit=limit, timeout=timeout, allowed_updates=allowed_updates,
        long_polling_timeout=long_polling_timeout)
  File "C:\Users\Administrator\AppData\Local\Programs\Python\Python313\Lib\site-packages\telebot\apihelper.py", line 321, in get_updates
    return _make_request(token, method_url, params=payload)
  File "C:\Users\Administrator\AppData\Local\Programs\Python\Python313\Lib\site-packages\telebot\apihelper.py", line 164, in _make_request
    json_result = _check_result(method_name, result)
  File "C:\Users\Administrator\AppData\Local\Programs\Python\Python313\Lib\site-packages\telebot\apihelper.py", line 191, in _check_result
    raise ApiTelegramException(method_name, result, result_json)
telebot.apihelper.ApiTelegramException: A request to the Telegram API was unsuccessful. Error code: 409. Description: Conflict: terminated by other getUpdates request; make sure that only one bot instance is running

2025-05-05 15:55:08,797 - Threaded polling exception: A request to the Telegram API was unsuccessful. Error code: 409. Description: Conflict: terminated by other getUpdates request; make sure that only one bot instance is running
2025-05-05 15:55:08,799 - Exception traceback:
Traceback (most recent call last):
  File "C:\Users\Administrator\AppData\Local\Programs\Python\Python313\Lib\site-packages\telebot\__init__.py", line 1140, in __threaded_polling
    polling_thread.raise_exceptions()
    ~~~~~~~~~~~~~~~~~~~~~~~~~~~~~~~^^
  File "C:\Users\Administrator\AppData\Local\Programs\Python\Python313\Lib\site-packages\telebot\util.py", line 110, in raise_exceptions
    raise self.exception_info
  File "C:\Users\Administrator\AppData\Local\Programs\Python\Python313\Lib\site-packages\telebot\util.py", line 92, in run
    task(*args, **kwargs)
    ~~~~^^^^^^^^^^^^^^^^^
  File "C:\Users\Administrator\AppData\Local\Programs\Python\Python313\Lib\site-packages\telebot\__init__.py", line 661, in __retrieve_updates
    updates = self.get_updates(offset=(self.last_update_id + 1),
                               allowed_updates=allowed_updates,
                               timeout=timeout, long_polling_timeout=long_polling_timeout)
  File "C:\Users\Administrator\AppData\Local\Programs\Python\Python313\Lib\site-packages\telebot\__init__.py", line 633, in get_updates
    json_updates = apihelper.get_updates(
        self.token, offset=offset, limit=limit, timeout=timeout, allowed_updates=allowed_updates,
        long_polling_timeout=long_polling_timeout)
  File "C:\Users\Administrator\AppData\Local\Programs\Python\Python313\Lib\site-packages\telebot\apihelper.py", line 321, in get_updates
    return _make_request(token, method_url, params=payload)
  File "C:\Users\Administrator\AppData\Local\Programs\Python\Python313\Lib\site-packages\telebot\apihelper.py", line 164, in _make_request
    json_result = _check_result(method_name, result)
  File "C:\Users\Administrator\AppData\Local\Programs\Python\Python313\Lib\site-packages\telebot\apihelper.py", line 191, in _check_result
    raise ApiTelegramException(method_name, result, result_json)
telebot.apihelper.ApiTelegramException: A request to the Telegram API was unsuccessful. Error code: 409. Description: Conflict: terminated by other getUpdates request; make sure that only one bot instance is running

2025-05-05 15:55:14,038 - Threaded polling exception: A request to the Telegram API was unsuccessful. Error code: 409. Description: Conflict: terminated by other getUpdates request; make sure that only one bot instance is running
2025-05-05 15:55:14,040 - Exception traceback:
Traceback (most recent call last):
  File "C:\Users\Administrator\AppData\Local\Programs\Python\Python313\Lib\site-packages\telebot\__init__.py", line 1140, in __threaded_polling
    polling_thread.raise_exceptions()
    ~~~~~~~~~~~~~~~~~~~~~~~~~~~~~~~^^
  File "C:\Users\Administrator\AppData\Local\Programs\Python\Python313\Lib\site-packages\telebot\util.py", line 110, in raise_exceptions
    raise self.exception_info
  File "C:\Users\Administrator\AppData\Local\Programs\Python\Python313\Lib\site-packages\telebot\util.py", line 92, in run
    task(*args, **kwargs)
    ~~~~^^^^^^^^^^^^^^^^^
  File "C:\Users\Administrator\AppData\Local\Programs\Python\Python313\Lib\site-packages\telebot\__init__.py", line 661, in __retrieve_updates
    updates = self.get_updates(offset=(self.last_update_id + 1),
                               allowed_updates=allowed_updates,
                               timeout=timeout, long_polling_timeout=long_polling_timeout)
  File "C:\Users\Administrator\AppData\Local\Programs\Python\Python313\Lib\site-packages\telebot\__init__.py", line 633, in get_updates
    json_updates = apihelper.get_updates(
        self.token, offset=offset, limit=limit, timeout=timeout, allowed_updates=allowed_updates,
        long_polling_timeout=long_polling_timeout)
  File "C:\Users\Administrator\AppData\Local\Programs\Python\Python313\Lib\site-packages\telebot\apihelper.py", line 321, in get_updates
    return _make_request(token, method_url, params=payload)
  File "C:\Users\Administrator\AppData\Local\Programs\Python\Python313\Lib\site-packages\telebot\apihelper.py", line 164, in _make_request
    json_result = _check_result(method_name, result)
  File "C:\Users\Administrator\AppData\Local\Programs\Python\Python313\Lib\site-packages\telebot\apihelper.py", line 191, in _check_result
    raise ApiTelegramException(method_name, result, result_json)
telebot.apihelper.ApiTelegramException: A request to the Telegram API was unsuccessful. Error code: 409. Description: Conflict: terminated by other getUpdates request; make sure that only one bot instance is running

2025-05-05 15:55:18,261 - Threaded polling exception: A request to the Telegram API was unsuccessful. Error code: 409. Description: Conflict: terminated by other getUpdates request; make sure that only one bot instance is running
2025-05-05 15:55:18,263 - Exception traceback:
Traceback (most recent call last):
  File "C:\Users\Administrator\AppData\Local\Programs\Python\Python313\Lib\site-packages\telebot\__init__.py", line 1140, in __threaded_polling
    polling_thread.raise_exceptions()
    ~~~~~~~~~~~~~~~~~~~~~~~~~~~~~~~^^
  File "C:\Users\Administrator\AppData\Local\Programs\Python\Python313\Lib\site-packages\telebot\util.py", line 110, in raise_exceptions
    raise self.exception_info
  File "C:\Users\Administrator\AppData\Local\Programs\Python\Python313\Lib\site-packages\telebot\util.py", line 92, in run
    task(*args, **kwargs)
    ~~~~^^^^^^^^^^^^^^^^^
  File "C:\Users\Administrator\AppData\Local\Programs\Python\Python313\Lib\site-packages\telebot\__init__.py", line 661, in __retrieve_updates
    updates = self.get_updates(offset=(self.last_update_id + 1),
                               allowed_updates=allowed_updates,
                               timeout=timeout, long_polling_timeout=long_polling_timeout)
  File "C:\Users\Administrator\AppData\Local\Programs\Python\Python313\Lib\site-packages\telebot\__init__.py", line 633, in get_updates
    json_updates = apihelper.get_updates(
        self.token, offset=offset, limit=limit, timeout=timeout, allowed_updates=allowed_updates,
        long_polling_timeout=long_polling_timeout)
  File "C:\Users\Administrator\AppData\Local\Programs\Python\Python313\Lib\site-packages\telebot\apihelper.py", line 321, in get_updates
    return _make_request(token, method_url, params=payload)
  File "C:\Users\Administrator\AppData\Local\Programs\Python\Python313\Lib\site-packages\telebot\apihelper.py", line 164, in _make_request
    json_result = _check_result(method_name, result)
  File "C:\Users\Administrator\AppData\Local\Programs\Python\Python313\Lib\site-packages\telebot\apihelper.py", line 191, in _check_result
    raise ApiTelegramException(method_name, result, result_json)
telebot.apihelper.ApiTelegramException: A request to the Telegram API was unsuccessful. Error code: 409. Description: Conflict: terminated by other getUpdates request; make sure that only one bot instance is running

2025-05-05 15:55:22,482 - Threaded polling exception: A request to the Telegram API was unsuccessful. Error code: 409. Description: Conflict: terminated by other getUpdates request; make sure that only one bot instance is running
2025-05-05 15:55:22,484 - Exception traceback:
Traceback (most recent call last):
  File "C:\Users\Administrator\AppData\Local\Programs\Python\Python313\Lib\site-packages\telebot\__init__.py", line 1140, in __threaded_polling
    polling_thread.raise_exceptions()
    ~~~~~~~~~~~~~~~~~~~~~~~~~~~~~~~^^
  File "C:\Users\Administrator\AppData\Local\Programs\Python\Python313\Lib\site-packages\telebot\util.py", line 110, in raise_exceptions
    raise self.exception_info
  File "C:\Users\Administrator\AppData\Local\Programs\Python\Python313\Lib\site-packages\telebot\util.py", line 92, in run
    task(*args, **kwargs)
    ~~~~^^^^^^^^^^^^^^^^^
  File "C:\Users\Administrator\AppData\Local\Programs\Python\Python313\Lib\site-packages\telebot\__init__.py", line 661, in __retrieve_updates
    updates = self.get_updates(offset=(self.last_update_id + 1),
                               allowed_updates=allowed_updates,
                               timeout=timeout, long_polling_timeout=long_polling_timeout)
  File "C:\Users\Administrator\AppData\Local\Programs\Python\Python313\Lib\site-packages\telebot\__init__.py", line 633, in get_updates
    json_updates = apihelper.get_updates(
        self.token, offset=offset, limit=limit, timeout=timeout, allowed_updates=allowed_updates,
        long_polling_timeout=long_polling_timeout)
  File "C:\Users\Administrator\AppData\Local\Programs\Python\Python313\Lib\site-packages\telebot\apihelper.py", line 321, in get_updates
    return _make_request(token, method_url, params=payload)
  File "C:\Users\Administrator\AppData\Local\Programs\Python\Python313\Lib\site-packages\telebot\apihelper.py", line 164, in _make_request
    json_result = _check_result(method_name, result)
  File "C:\Users\Administrator\AppData\Local\Programs\Python\Python313\Lib\site-packages\telebot\apihelper.py", line 191, in _check_result
    raise ApiTelegramException(method_name, result, result_json)
telebot.apihelper.ApiTelegramException: A request to the Telegram API was unsuccessful. Error code: 409. Description: Conflict: terminated by other getUpdates request; make sure that only one bot instance is running

2025-05-05 15:55:37,454 - Ê©üÂô®‰∫∫Â∑≤ÂïüÂãï...
2025-05-05 15:55:38,823 - Threaded polling exception: A request to the Telegram API was unsuccessful. Error code: 409. Description: Conflict: terminated by other getUpdates request; make sure that only one bot instance is running
2025-05-05 15:55:38,827 - Exception traceback:
Traceback (most recent call last):
  File "C:\Users\Administrator\AppData\Local\Programs\Python\Python313\Lib\site-packages\telebot\__init__.py", line 1140, in __threaded_polling
    polling_thread.raise_exceptions()
    ~~~~~~~~~~~~~~~~~~~~~~~~~~~~~~~^^
  File "C:\Users\Administrator\AppData\Local\Programs\Python\Python313\Lib\site-packages\telebot\util.py", line 110, in raise_exceptions
    raise self.exception_info
  File "C:\Users\Administrator\AppData\Local\Programs\Python\Python313\Lib\site-packages\telebot\util.py", line 92, in run
    task(*args, **kwargs)
    ~~~~^^^^^^^^^^^^^^^^^
  File "C:\Users\Administrator\AppData\Local\Programs\Python\Python313\Lib\site-packages\telebot\__init__.py", line 661, in __retrieve_updates
    updates = self.get_updates(offset=(self.last_update_id + 1),
                               allowed_updates=allowed_updates,
                               timeout=timeout, long_polling_timeout=long_polling_timeout)
  File "C:\Users\Administrator\AppData\Local\Programs\Python\Python313\Lib\site-packages\telebot\__init__.py", line 633, in get_updates
    json_updates = apihelper.get_updates(
        self.token, offset=offset, limit=limit, timeout=timeout, allowed_updates=allowed_updates,
        long_polling_timeout=long_polling_timeout)
  File "C:\Users\Administrator\AppData\Local\Programs\Python\Python313\Lib\site-packages\telebot\apihelper.py", line 321, in get_updates
    return _make_request(token, method_url, params=payload)
  File "C:\Users\Administrator\AppData\Local\Programs\Python\Python313\Lib\site-packages\telebot\apihelper.py", line 164, in _make_request
    json_result = _check_result(method_name, result)
  File "C:\Users\Administrator\AppData\Local\Programs\Python\Python313\Lib\site-packages\telebot\apihelper.py", line 191, in _check_result
    raise ApiTelegramException(method_name, result, result_json)
telebot.apihelper.ApiTelegramException: A request to the Telegram API was unsuccessful. Error code: 409. Description: Conflict: terminated by other getUpdates request; make sure that only one bot instance is running

2025-05-05 15:55:45,874 - Infinity polling exception: KeyboardButton.__init__() got an unexpected keyword argument 'callback_data'
2025-05-05 15:55:45,879 - Exception traceback:
Traceback (most recent call last):
  File "C:\Users\Administrator\AppData\Local\Programs\Python\Python313\Lib\site-packages\telebot\__init__.py", line 1016, in infinity_polling
    self.polling(non_stop=True, timeout=timeout, long_polling_timeout=long_polling_timeout,
    ~~~~~~~~~~~~^^^^^^^^^^^^^^^^^^^^^^^^^^^^^^^^^^^^^^^^^^^^^^^^^^^^^^^^^^^^^^^^^^^^^^^^^^^
                 logger_level=logger_level, allowed_updates=allowed_updates, restart_on_change=False,
                 ^^^^^^^^^^^^^^^^^^^^^^^^^^^^^^^^^^^^^^^^^^^^^^^^^^^^^^^^^^^^^^^^^^^^^^^^^^^^^^^^^^^^
                 *args, **kwargs)
                 ^^^^^^^^^^^^^^^^
  File "C:\Users\Administrator\AppData\Local\Programs\Python\Python313\Lib\site-packages\telebot\__init__.py", line 1104, in polling
    self.__threaded_polling(non_stop=non_stop, interval=interval, timeout=timeout, long_polling_timeout=long_polling_timeout,
    ~~~~~~~~~~~~~~~~~~~~~~~^^^^^^^^^^^^^^^^^^^^^^^^^^^^^^^^^^^^^^^^^^^^^^^^^^^^^^^^^^^^^^^^^^^^^^^^^^^^^^^^^^^^^^^^^^^^^^^^^^
                            logger_level=logger_level, allowed_updates=allowed_updates)
                            ^^^^^^^^^^^^^^^^^^^^^^^^^^^^^^^^^^^^^^^^^^^^^^^^^^^^^^^^^^^
  File "C:\Users\Administrator\AppData\Local\Programs\Python\Python313\Lib\site-packages\telebot\__init__.py", line 1179, in __threaded_polling
    raise e
  File "C:\Users\Administrator\AppData\Local\Programs\Python\Python313\Lib\site-packages\telebot\__init__.py", line 1141, in __threaded_polling
    self.worker_pool.raise_exceptions()
    ~~~~~~~~~~~~~~~~~~~~~~~~~~~~~~~~~^^
  File "C:\Users\Administrator\AppData\Local\Programs\Python\Python313\Lib\site-packages\telebot\util.py", line 149, in raise_exceptions
    raise self.exception_info
  File "C:\Users\Administrator\AppData\Local\Programs\Python\Python313\Lib\site-packages\telebot\util.py", line 92, in run
    task(*args, **kwargs)
    ~~~~^^^^^^^^^^^^^^^^^
  File "C:\Users\Administrator\AppData\Local\Programs\Python\Python313\Lib\site-packages\telebot\__init__.py", line 7860, in _run_middlewares_and_handler
    result = handler['function'](message)
  File "C:\Telegram Bot\AccountBot\bot.py", line 1839, in handle_change_notify_toggle
    bot.reply_to(message, f'Áï∞ÂãïÊèêÈÜí{status}', reply_markup=create_main_menu())
                                                            ~~~~~~~~~~~~~~~~^^
  File "C:\Telegram Bot\AccountBot\bot.py", line 114, in create_main_menu
    KeyboardButton('üîÑÔ∏èÈáçÊñ∞ÂïüÂãï', callback_data=None)  # ÊåâÈàïÂêçÁ®±ÊîπÁÇ∫„ÄéüîÑÔ∏èÈáçÊñ∞ÂïüÂãï„Äè
    ~~~~~~~~~~~~~~^^^^^^^^^^^^^^^^^^^^^^^^^^^^^^^^^^^
TypeError: KeyboardButton.__init__() got an unexpected keyword argument 'callback_data'

2025-05-05 15:55:52,534 - Threaded polling exception: A request to the Telegram API was unsuccessful. Error code: 409. Description: Conflict: terminated by other getUpdates request; make sure that only one bot instance is running
2025-05-05 15:55:52,538 - Exception traceback:
Traceback (most recent call last):
  File "C:\Users\Administrator\AppData\Local\Programs\Python\Python313\Lib\site-packages\telebot\__init__.py", line 1140, in __threaded_polling
    polling_thread.raise_exceptions()
    ~~~~~~~~~~~~~~~~~~~~~~~~~~~~~~~^^
  File "C:\Users\Administrator\AppData\Local\Programs\Python\Python313\Lib\site-packages\telebot\util.py", line 110, in raise_exceptions
    raise self.exception_info
  File "C:\Users\Administrator\AppData\Local\Programs\Python\Python313\Lib\site-packages\telebot\util.py", line 92, in run
    task(*args, **kwargs)
    ~~~~^^^^^^^^^^^^^^^^^
  File "C:\Users\Administrator\AppData\Local\Programs\Python\Python313\Lib\site-packages\telebot\__init__.py", line 661, in __retrieve_updates
    updates = self.get_updates(offset=(self.last_update_id + 1),
                               allowed_updates=allowed_updates,
                               timeout=timeout, long_polling_timeout=long_polling_timeout)
  File "C:\Users\Administrator\AppData\Local\Programs\Python\Python313\Lib\site-packages\telebot\__init__.py", line 633, in get_updates
    json_updates = apihelper.get_updates(
        self.token, offset=offset, limit=limit, timeout=timeout, allowed_updates=allowed_updates,
        long_polling_timeout=long_polling_timeout)
  File "C:\Users\Administrator\AppData\Local\Programs\Python\Python313\Lib\site-packages\telebot\apihelper.py", line 321, in get_updates
    return _make_request(token, method_url, params=payload)
  File "C:\Users\Administrator\AppData\Local\Programs\Python\Python313\Lib\site-packages\telebot\apihelper.py", line 164, in _make_request
    json_result = _check_result(method_name, result)
  File "C:\Users\Administrator\AppData\Local\Programs\Python\Python313\Lib\site-packages\telebot\apihelper.py", line 191, in _check_result
    raise ApiTelegramException(method_name, result, result_json)
telebot.apihelper.ApiTelegramException: A request to the Telegram API was unsuccessful. Error code: 409. Description: Conflict: terminated by other getUpdates request; make sure that only one bot instance is running

2025-05-05 15:56:08,757 - Threaded polling exception: A request to the Telegram API was unsuccessful. Error code: 409. Description: Conflict: terminated by other getUpdates request; make sure that only one bot instance is running
2025-05-05 15:56:08,762 - Exception traceback:
Traceback (most recent call last):
  File "C:\Users\Administrator\AppData\Local\Programs\Python\Python313\Lib\site-packages\telebot\__init__.py", line 1140, in __threaded_polling
    polling_thread.raise_exceptions()
    ~~~~~~~~~~~~~~~~~~~~~~~~~~~~~~~^^
  File "C:\Users\Administrator\AppData\Local\Programs\Python\Python313\Lib\site-packages\telebot\util.py", line 110, in raise_exceptions
    raise self.exception_info
  File "C:\Users\Administrator\AppData\Local\Programs\Python\Python313\Lib\site-packages\telebot\util.py", line 92, in run
    task(*args, **kwargs)
    ~~~~^^^^^^^^^^^^^^^^^
  File "C:\Users\Administrator\AppData\Local\Programs\Python\Python313\Lib\site-packages\telebot\__init__.py", line 661, in __retrieve_updates
    updates = self.get_updates(offset=(self.last_update_id + 1),
                               allowed_updates=allowed_updates,
                               timeout=timeout, long_polling_timeout=long_polling_timeout)
  File "C:\Users\Administrator\AppData\Local\Programs\Python\Python313\Lib\site-packages\telebot\__init__.py", line 633, in get_updates
    json_updates = apihelper.get_updates(
        self.token, offset=offset, limit=limit, timeout=timeout, allowed_updates=allowed_updates,
        long_polling_timeout=long_polling_timeout)
  File "C:\Users\Administrator\AppData\Local\Programs\Python\Python313\Lib\site-packages\telebot\apihelper.py", line 321, in get_updates
    return _make_request(token, method_url, params=payload)
  File "C:\Users\Administrator\AppData\Local\Programs\Python\Python313\Lib\site-packages\telebot\apihelper.py", line 164, in _make_request
    json_result = _check_result(method_name, result)
  File "C:\Users\Administrator\AppData\Local\Programs\Python\Python313\Lib\site-packages\telebot\apihelper.py", line 191, in _check_result
    raise ApiTelegramException(method_name, result, result_json)
telebot.apihelper.ApiTelegramException: A request to the Telegram API was unsuccessful. Error code: 409. Description: Conflict: terminated by other getUpdates request; make sure that only one bot instance is running

2025-05-05 15:56:12,235 - Threaded polling exception: A request to the Telegram API was unsuccessful. Error code: 409. Description: Conflict: terminated by other getUpdates request; make sure that only one bot instance is running
2025-05-05 15:56:12,237 - Exception traceback:
Traceback (most recent call last):
  File "C:\Users\Administrator\AppData\Local\Programs\Python\Python313\Lib\site-packages\telebot\__init__.py", line 1140, in __threaded_polling
    polling_thread.raise_exceptions()
    ~~~~~~~~~~~~~~~~~~~~~~~~~~~~~~~^^
  File "C:\Users\Administrator\AppData\Local\Programs\Python\Python313\Lib\site-packages\telebot\util.py", line 110, in raise_exceptions
    raise self.exception_info
  File "C:\Users\Administrator\AppData\Local\Programs\Python\Python313\Lib\site-packages\telebot\util.py", line 92, in run
    task(*args, **kwargs)
    ~~~~^^^^^^^^^^^^^^^^^
  File "C:\Users\Administrator\AppData\Local\Programs\Python\Python313\Lib\site-packages\telebot\__init__.py", line 661, in __retrieve_updates
    updates = self.get_updates(offset=(self.last_update_id + 1),
                               allowed_updates=allowed_updates,
                               timeout=timeout, long_polling_timeout=long_polling_timeout)
  File "C:\Users\Administrator\AppData\Local\Programs\Python\Python313\Lib\site-packages\telebot\__init__.py", line 633, in get_updates
    json_updates = apihelper.get_updates(
        self.token, offset=offset, limit=limit, timeout=timeout, allowed_updates=allowed_updates,
        long_polling_timeout=long_polling_timeout)
  File "C:\Users\Administrator\AppData\Local\Programs\Python\Python313\Lib\site-packages\telebot\apihelper.py", line 321, in get_updates
    return _make_request(token, method_url, params=payload)
  File "C:\Users\Administrator\AppData\Local\Programs\Python\Python313\Lib\site-packages\telebot\apihelper.py", line 164, in _make_request
    json_result = _check_result(method_name, result)
  File "C:\Users\Administrator\AppData\Local\Programs\Python\Python313\Lib\site-packages\telebot\apihelper.py", line 191, in _check_result
    raise ApiTelegramException(method_name, result, result_json)
telebot.apihelper.ApiTelegramException: A request to the Telegram API was unsuccessful. Error code: 409. Description: Conflict: terminated by other getUpdates request; make sure that only one bot instance is running

2025-05-05 15:56:44,455 - Threaded polling exception: A request to the Telegram API was unsuccessful. Error code: 409. Description: Conflict: terminated by other getUpdates request; make sure that only one bot instance is running
2025-05-05 15:56:44,457 - Exception traceback:
Traceback (most recent call last):
  File "C:\Users\Administrator\AppData\Local\Programs\Python\Python313\Lib\site-packages\telebot\__init__.py", line 1140, in __threaded_polling
    polling_thread.raise_exceptions()
    ~~~~~~~~~~~~~~~~~~~~~~~~~~~~~~~^^
  File "C:\Users\Administrator\AppData\Local\Programs\Python\Python313\Lib\site-packages\telebot\util.py", line 110, in raise_exceptions
    raise self.exception_info
  File "C:\Users\Administrator\AppData\Local\Programs\Python\Python313\Lib\site-packages\telebot\util.py", line 92, in run
    task(*args, **kwargs)
    ~~~~^^^^^^^^^^^^^^^^^
  File "C:\Users\Administrator\AppData\Local\Programs\Python\Python313\Lib\site-packages\telebot\__init__.py", line 661, in __retrieve_updates
    updates = self.get_updates(offset=(self.last_update_id + 1),
                               allowed_updates=allowed_updates,
                               timeout=timeout, long_polling_timeout=long_polling_timeout)
  File "C:\Users\Administrator\AppData\Local\Programs\Python\Python313\Lib\site-packages\telebot\__init__.py", line 633, in get_updates
    json_updates = apihelper.get_updates(
        self.token, offset=offset, limit=limit, timeout=timeout, allowed_updates=allowed_updates,
        long_polling_timeout=long_polling_timeout)
  File "C:\Users\Administrator\AppData\Local\Programs\Python\Python313\Lib\site-packages\telebot\apihelper.py", line 321, in get_updates
    return _make_request(token, method_url, params=payload)
  File "C:\Users\Administrator\AppData\Local\Programs\Python\Python313\Lib\site-packages\telebot\apihelper.py", line 164, in _make_request
    json_result = _check_result(method_name, result)
  File "C:\Users\Administrator\AppData\Local\Programs\Python\Python313\Lib\site-packages\telebot\apihelper.py", line 191, in _check_result
    raise ApiTelegramException(method_name, result, result_json)
telebot.apihelper.ApiTelegramException: A request to the Telegram API was unsuccessful. Error code: 409. Description: Conflict: terminated by other getUpdates request; make sure that only one bot instance is running

2025-05-05 15:56:47,925 - Threaded polling exception: A request to the Telegram API was unsuccessful. Error code: 409. Description: Conflict: terminated by other getUpdates request; make sure that only one bot instance is running
2025-05-05 15:56:47,926 - Exception traceback:
Traceback (most recent call last):
  File "C:\Users\Administrator\AppData\Local\Programs\Python\Python313\Lib\site-packages\telebot\__init__.py", line 1140, in __threaded_polling
    polling_thread.raise_exceptions()
    ~~~~~~~~~~~~~~~~~~~~~~~~~~~~~~~^^
  File "C:\Users\Administrator\AppData\Local\Programs\Python\Python313\Lib\site-packages\telebot\util.py", line 110, in raise_exceptions
    raise self.exception_info
  File "C:\Users\Administrator\AppData\Local\Programs\Python\Python313\Lib\site-packages\telebot\util.py", line 92, in run
    task(*args, **kwargs)
    ~~~~^^^^^^^^^^^^^^^^^
  File "C:\Users\Administrator\AppData\Local\Programs\Python\Python313\Lib\site-packages\telebot\__init__.py", line 661, in __retrieve_updates
    updates = self.get_updates(offset=(self.last_update_id + 1),
                               allowed_updates=allowed_updates,
                               timeout=timeout, long_polling_timeout=long_polling_timeout)
  File "C:\Users\Administrator\AppData\Local\Programs\Python\Python313\Lib\site-packages\telebot\__init__.py", line 633, in get_updates
    json_updates = apihelper.get_updates(
        self.token, offset=offset, limit=limit, timeout=timeout, allowed_updates=allowed_updates,
        long_polling_timeout=long_polling_timeout)
  File "C:\Users\Administrator\AppData\Local\Programs\Python\Python313\Lib\site-packages\telebot\apihelper.py", line 321, in get_updates
    return _make_request(token, method_url, params=payload)
  File "C:\Users\Administrator\AppData\Local\Programs\Python\Python313\Lib\site-packages\telebot\apihelper.py", line 164, in _make_request
    json_result = _check_result(method_name, result)
  File "C:\Users\Administrator\AppData\Local\Programs\Python\Python313\Lib\site-packages\telebot\apihelper.py", line 191, in _check_result
    raise ApiTelegramException(method_name, result, result_json)
telebot.apihelper.ApiTelegramException: A request to the Telegram API was unsuccessful. Error code: 409. Description: Conflict: terminated by other getUpdates request; make sure that only one bot instance is running

2025-05-05 15:58:14,321 - Ê©üÂô®‰∫∫Â∑≤ÂïüÂãï...
2025-05-05 15:58:29,370 - Infinity polling exception: name 'get_current_month_report_message' is not defined
2025-05-05 15:58:29,377 - Exception traceback:
Traceback (most recent call last):
  File "c:\Telegram Bot\AccountBot\.venv\Lib\site-packages\telebot\__init__.py", line 957, in infinity_polling
    self.polling(non_stop=True, timeout=timeout, long_polling_timeout=long_polling_timeout,
    ~~~~~~~~~~~~^^^^^^^^^^^^^^^^^^^^^^^^^^^^^^^^^^^^^^^^^^^^^^^^^^^^^^^^^^^^^^^^^^^^^^^^^^^
                 logger_level=logger_level, allowed_updates=allowed_updates, restart_on_change=False,
                 ^^^^^^^^^^^^^^^^^^^^^^^^^^^^^^^^^^^^^^^^^^^^^^^^^^^^^^^^^^^^^^^^^^^^^^^^^^^^^^^^^^^^
                 *args, **kwargs)
                 ^^^^^^^^^^^^^^^^
  File "c:\Telegram Bot\AccountBot\.venv\Lib\site-packages\telebot\__init__.py", line 1045, in polling
    self.__threaded_polling(non_stop=non_stop, interval=interval, timeout=timeout, long_polling_timeout=long_polling_timeout,
    ~~~~~~~~~~~~~~~~~~~~~~~^^^^^^^^^^^^^^^^^^^^^^^^^^^^^^^^^^^^^^^^^^^^^^^^^^^^^^^^^^^^^^^^^^^^^^^^^^^^^^^^^^^^^^^^^^^^^^^^^^
                            logger_level=logger_level, allowed_updates=allowed_updates)
                            ^^^^^^^^^^^^^^^^^^^^^^^^^^^^^^^^^^^^^^^^^^^^^^^^^^^^^^^^^^^
  File "c:\Telegram Bot\AccountBot\.venv\Lib\site-packages\telebot\__init__.py", line 1120, in __threaded_polling
    raise e
  File "c:\Telegram Bot\AccountBot\.venv\Lib\site-packages\telebot\__init__.py", line 1082, in __threaded_polling
    self.worker_pool.raise_exceptions()
    ~~~~~~~~~~~~~~~~~~~~~~~~~~~~~~~~~^^
  File "c:\Telegram Bot\AccountBot\.venv\Lib\site-packages\telebot\util.py", line 147, in raise_exceptions
    raise self.exception_info
  File "c:\Telegram Bot\AccountBot\.venv\Lib\site-packages\telebot\util.py", line 90, in run
    task(*args, **kwargs)
    ~~~~^^^^^^^^^^^^^^^^^
  File "c:\Telegram Bot\AccountBot\.venv\Lib\site-packages\telebot\__init__.py", line 6793, in _run_middlewares_and_handler
    result = handler['function'](message)
  File "bot.py", line 1643, in handle_history_report
    msg += get_current_month_report_message()
           ^^^^^^^^^^^^^^^^^^^^^^^^^^^^^^^^
NameError: name 'get_current_month_report_message' is not defined

2025-05-05 15:59:41,234 - Infinity polling exception: name 'get_current_month_report_message' is not defined
2025-05-05 15:59:41,241 - Exception traceback:
Traceback (most recent call last):
  File "c:\Telegram Bot\AccountBot\.venv\Lib\site-packages\telebot\__init__.py", line 957, in infinity_polling
    self.polling(non_stop=True, timeout=timeout, long_polling_timeout=long_polling_timeout,
    ~~~~~~~~~~~~^^^^^^^^^^^^^^^^^^^^^^^^^^^^^^^^^^^^^^^^^^^^^^^^^^^^^^^^^^^^^^^^^^^^^^^^^^^
                 logger_level=logger_level, allowed_updates=allowed_updates, restart_on_change=False,
                 ^^^^^^^^^^^^^^^^^^^^^^^^^^^^^^^^^^^^^^^^^^^^^^^^^^^^^^^^^^^^^^^^^^^^^^^^^^^^^^^^^^^^
                 *args, **kwargs)
                 ^^^^^^^^^^^^^^^^
  File "c:\Telegram Bot\AccountBot\.venv\Lib\site-packages\telebot\__init__.py", line 1045, in polling
    self.__threaded_polling(non_stop=non_stop, interval=interval, timeout=timeout, long_polling_timeout=long_polling_timeout,
    ~~~~~~~~~~~~~~~~~~~~~~~^^^^^^^^^^^^^^^^^^^^^^^^^^^^^^^^^^^^^^^^^^^^^^^^^^^^^^^^^^^^^^^^^^^^^^^^^^^^^^^^^^^^^^^^^^^^^^^^^^
                            logger_level=logger_level, allowed_updates=allowed_updates)
                            ^^^^^^^^^^^^^^^^^^^^^^^^^^^^^^^^^^^^^^^^^^^^^^^^^^^^^^^^^^^
  File "c:\Telegram Bot\AccountBot\.venv\Lib\site-packages\telebot\__init__.py", line 1120, in __threaded_polling
    raise e
  File "c:\Telegram Bot\AccountBot\.venv\Lib\site-packages\telebot\__init__.py", line 1082, in __threaded_polling
    self.worker_pool.raise_exceptions()
    ~~~~~~~~~~~~~~~~~~~~~~~~~~~~~~~~~^^
  File "c:\Telegram Bot\AccountBot\.venv\Lib\site-packages\telebot\util.py", line 147, in raise_exceptions
    raise self.exception_info
  File "c:\Telegram Bot\AccountBot\.venv\Lib\site-packages\telebot\util.py", line 90, in run
    task(*args, **kwargs)
    ~~~~^^^^^^^^^^^^^^^^^
  File "c:\Telegram Bot\AccountBot\.venv\Lib\site-packages\telebot\__init__.py", line 6793, in _run_middlewares_and_handler
    result = handler['function'](message)
  File "bot.py", line 1643, in handle_history_report
    msg += get_current_month_report_message()
           ^^^^^^^^^^^^^^^^^^^^^^^^^^^^^^^^
NameError: name 'get_current_month_report_message' is not defined

2025-05-05 16:00:02,552 - Infinity polling exception: KeyboardButton.__init__() got an unexpected keyword argument 'callback_data'
2025-05-05 16:00:02,562 - Exception traceback:
Traceback (most recent call last):
  File "c:\Telegram Bot\AccountBot\.venv\Lib\site-packages\telebot\__init__.py", line 957, in infinity_polling
    self.polling(non_stop=True, timeout=timeout, long_polling_timeout=long_polling_timeout,
    ~~~~~~~~~~~~^^^^^^^^^^^^^^^^^^^^^^^^^^^^^^^^^^^^^^^^^^^^^^^^^^^^^^^^^^^^^^^^^^^^^^^^^^^
                 logger_level=logger_level, allowed_updates=allowed_updates, restart_on_change=False,
                 ^^^^^^^^^^^^^^^^^^^^^^^^^^^^^^^^^^^^^^^^^^^^^^^^^^^^^^^^^^^^^^^^^^^^^^^^^^^^^^^^^^^^
                 *args, **kwargs)
                 ^^^^^^^^^^^^^^^^
  File "c:\Telegram Bot\AccountBot\.venv\Lib\site-packages\telebot\__init__.py", line 1045, in polling
    self.__threaded_polling(non_stop=non_stop, interval=interval, timeout=timeout, long_polling_timeout=long_polling_timeout,
    ~~~~~~~~~~~~~~~~~~~~~~~^^^^^^^^^^^^^^^^^^^^^^^^^^^^^^^^^^^^^^^^^^^^^^^^^^^^^^^^^^^^^^^^^^^^^^^^^^^^^^^^^^^^^^^^^^^^^^^^^^
                            logger_level=logger_level, allowed_updates=allowed_updates)
                            ^^^^^^^^^^^^^^^^^^^^^^^^^^^^^^^^^^^^^^^^^^^^^^^^^^^^^^^^^^^
  File "c:\Telegram Bot\AccountBot\.venv\Lib\site-packages\telebot\__init__.py", line 1120, in __threaded_polling
    raise e
  File "c:\Telegram Bot\AccountBot\.venv\Lib\site-packages\telebot\__init__.py", line 1082, in __threaded_polling
    self.worker_pool.raise_exceptions()
    ~~~~~~~~~~~~~~~~~~~~~~~~~~~~~~~~~^^
  File "c:\Telegram Bot\AccountBot\.venv\Lib\site-packages\telebot\util.py", line 147, in raise_exceptions
    raise self.exception_info
  File "c:\Telegram Bot\AccountBot\.venv\Lib\site-packages\telebot\util.py", line 90, in run
    task(*args, **kwargs)
    ~~~~^^^^^^^^^^^^^^^^^
  File "c:\Telegram Bot\AccountBot\.venv\Lib\site-packages\telebot\__init__.py", line 6793, in _run_middlewares_and_handler
    result = handler['function'](message)
  File "bot.py", line 1635, in show_main_menu
    bot.send_message(message.chat.id, 'Ë´ãÈÅ∏ÊìáÂäüËÉΩÔºö', reply_markup=create_main_menu())
                                                                   ~~~~~~~~~~~~~~~~^^
  File "bot.py", line 114, in create_main_menu
    KeyboardButton('üîÑÔ∏èÈáçÊñ∞ÂïüÂãï', callback_data=None)  # ÊåâÈàïÂêçÁ®±ÊîπÁÇ∫„ÄéüîÑÔ∏èÈáçÊñ∞ÂïüÂãï„Äè
    ~~~~~~~~~~~~~~^^^^^^^^^^^^^^^^^^^^^^^^^^^^^^^^^^^
TypeError: KeyboardButton.__init__() got an unexpected keyword argument 'callback_data'

2025-05-05 16:00:24,661 - Infinity polling exception: KeyboardButton.__init__() got an unexpected keyword argument 'callback_data'
2025-05-05 16:00:24,667 - Exception traceback:
Traceback (most recent call last):
  File "c:\Telegram Bot\AccountBot\.venv\Lib\site-packages\telebot\__init__.py", line 957, in infinity_polling
    self.polling(non_stop=True, timeout=timeout, long_polling_timeout=long_polling_timeout,
    ~~~~~~~~~~~~^^^^^^^^^^^^^^^^^^^^^^^^^^^^^^^^^^^^^^^^^^^^^^^^^^^^^^^^^^^^^^^^^^^^^^^^^^^
                 logger_level=logger_level, allowed_updates=allowed_updates, restart_on_change=False,
                 ^^^^^^^^^^^^^^^^^^^^^^^^^^^^^^^^^^^^^^^^^^^^^^^^^^^^^^^^^^^^^^^^^^^^^^^^^^^^^^^^^^^^
                 *args, **kwargs)
                 ^^^^^^^^^^^^^^^^
  File "c:\Telegram Bot\AccountBot\.venv\Lib\site-packages\telebot\__init__.py", line 1045, in polling
    self.__threaded_polling(non_stop=non_stop, interval=interval, timeout=timeout, long_polling_timeout=long_polling_timeout,
    ~~~~~~~~~~~~~~~~~~~~~~~^^^^^^^^^^^^^^^^^^^^^^^^^^^^^^^^^^^^^^^^^^^^^^^^^^^^^^^^^^^^^^^^^^^^^^^^^^^^^^^^^^^^^^^^^^^^^^^^^^
                            logger_level=logger_level, allowed_updates=allowed_updates)
                            ^^^^^^^^^^^^^^^^^^^^^^^^^^^^^^^^^^^^^^^^^^^^^^^^^^^^^^^^^^^
  File "c:\Telegram Bot\AccountBot\.venv\Lib\site-packages\telebot\__init__.py", line 1120, in __threaded_polling
    raise e
  File "c:\Telegram Bot\AccountBot\.venv\Lib\site-packages\telebot\__init__.py", line 1082, in __threaded_polling
    self.worker_pool.raise_exceptions()
    ~~~~~~~~~~~~~~~~~~~~~~~~~~~~~~~~~^^
  File "c:\Telegram Bot\AccountBot\.venv\Lib\site-packages\telebot\util.py", line 147, in raise_exceptions
    raise self.exception_info
  File "c:\Telegram Bot\AccountBot\.venv\Lib\site-packages\telebot\util.py", line 90, in run
    task(*args, **kwargs)
    ~~~~^^^^^^^^^^^^^^^^^
  File "c:\Telegram Bot\AccountBot\.venv\Lib\site-packages\telebot\__init__.py", line 6793, in _run_middlewares_and_handler
    result = handler['function'](message)
  File "bot.py", line 1839, in handle_change_notify_toggle
    bot.reply_to(message, f'Áï∞ÂãïÊèêÈÜí{status}', reply_markup=create_main_menu())
                                                            ~~~~~~~~~~~~~~~~^^
  File "bot.py", line 114, in create_main_menu
    KeyboardButton('üîÑÔ∏èÈáçÊñ∞ÂïüÂãï', callback_data=None)  # ÊåâÈàïÂêçÁ®±ÊîπÁÇ∫„ÄéüîÑÔ∏èÈáçÊñ∞ÂïüÂãï„Äè
    ~~~~~~~~~~~~~~^^^^^^^^^^^^^^^^^^^^^^^^^^^^^^^^^^^
TypeError: KeyboardButton.__init__() got an unexpected keyword argument 'callback_data'

2025-05-05 16:12:08,053 - Infinity polling exception: name 'get_current_month_report_message' is not defined
2025-05-05 16:12:08,060 - Exception traceback:
Traceback (most recent call last):
  File "c:\Telegram Bot\AccountBot\.venv\Lib\site-packages\telebot\__init__.py", line 957, in infinity_polling
    self.polling(non_stop=True, timeout=timeout, long_polling_timeout=long_polling_timeout,
    ~~~~~~~~~~~~^^^^^^^^^^^^^^^^^^^^^^^^^^^^^^^^^^^^^^^^^^^^^^^^^^^^^^^^^^^^^^^^^^^^^^^^^^^
                 logger_level=logger_level, allowed_updates=allowed_updates, restart_on_change=False,
                 ^^^^^^^^^^^^^^^^^^^^^^^^^^^^^^^^^^^^^^^^^^^^^^^^^^^^^^^^^^^^^^^^^^^^^^^^^^^^^^^^^^^^
                 *args, **kwargs)
                 ^^^^^^^^^^^^^^^^
  File "c:\Telegram Bot\AccountBot\.venv\Lib\site-packages\telebot\__init__.py", line 1045, in polling
    self.__threaded_polling(non_stop=non_stop, interval=interval, timeout=timeout, long_polling_timeout=long_polling_timeout,
    ~~~~~~~~~~~~~~~~~~~~~~~^^^^^^^^^^^^^^^^^^^^^^^^^^^^^^^^^^^^^^^^^^^^^^^^^^^^^^^^^^^^^^^^^^^^^^^^^^^^^^^^^^^^^^^^^^^^^^^^^^
                            logger_level=logger_level, allowed_updates=allowed_updates)
                            ^^^^^^^^^^^^^^^^^^^^^^^^^^^^^^^^^^^^^^^^^^^^^^^^^^^^^^^^^^^
  File "c:\Telegram Bot\AccountBot\.venv\Lib\site-packages\telebot\__init__.py", line 1120, in __threaded_polling
    raise e
  File "c:\Telegram Bot\AccountBot\.venv\Lib\site-packages\telebot\__init__.py", line 1082, in __threaded_polling
    self.worker_pool.raise_exceptions()
    ~~~~~~~~~~~~~~~~~~~~~~~~~~~~~~~~~^^
  File "c:\Telegram Bot\AccountBot\.venv\Lib\site-packages\telebot\util.py", line 147, in raise_exceptions
    raise self.exception_info
  File "c:\Telegram Bot\AccountBot\.venv\Lib\site-packages\telebot\util.py", line 90, in run
    task(*args, **kwargs)
    ~~~~^^^^^^^^^^^^^^^^^
  File "c:\Telegram Bot\AccountBot\.venv\Lib\site-packages\telebot\__init__.py", line 6793, in _run_middlewares_and_handler
    result = handler['function'](message)
  File "bot.py", line 1643, in handle_history_report
    msg += get_current_month_report_message()
           ^^^^^^^^^^^^^^^^^^^^^^^^^^^^^^^^
NameError: name 'get_current_month_report_message' is not defined

2025-05-05 16:38:30,627 - Infinity polling exception: name 'get_current_month_report_message' is not defined
2025-05-05 16:38:30,633 - Exception traceback:
Traceback (most recent call last):
  File "c:\Telegram Bot\AccountBot\.venv\Lib\site-packages\telebot\__init__.py", line 957, in infinity_polling
    self.polling(non_stop=True, timeout=timeout, long_polling_timeout=long_polling_timeout,
    ~~~~~~~~~~~~^^^^^^^^^^^^^^^^^^^^^^^^^^^^^^^^^^^^^^^^^^^^^^^^^^^^^^^^^^^^^^^^^^^^^^^^^^^
                 logger_level=logger_level, allowed_updates=allowed_updates, restart_on_change=False,
                 ^^^^^^^^^^^^^^^^^^^^^^^^^^^^^^^^^^^^^^^^^^^^^^^^^^^^^^^^^^^^^^^^^^^^^^^^^^^^^^^^^^^^
                 *args, **kwargs)
                 ^^^^^^^^^^^^^^^^
  File "c:\Telegram Bot\AccountBot\.venv\Lib\site-packages\telebot\__init__.py", line 1045, in polling
    self.__threaded_polling(non_stop=non_stop, interval=interval, timeout=timeout, long_polling_timeout=long_polling_timeout,
    ~~~~~~~~~~~~~~~~~~~~~~~^^^^^^^^^^^^^^^^^^^^^^^^^^^^^^^^^^^^^^^^^^^^^^^^^^^^^^^^^^^^^^^^^^^^^^^^^^^^^^^^^^^^^^^^^^^^^^^^^^
                            logger_level=logger_level, allowed_updates=allowed_updates)
                            ^^^^^^^^^^^^^^^^^^^^^^^^^^^^^^^^^^^^^^^^^^^^^^^^^^^^^^^^^^^
  File "c:\Telegram Bot\AccountBot\.venv\Lib\site-packages\telebot\__init__.py", line 1120, in __threaded_polling
    raise e
  File "c:\Telegram Bot\AccountBot\.venv\Lib\site-packages\telebot\__init__.py", line 1082, in __threaded_polling
    self.worker_pool.raise_exceptions()
    ~~~~~~~~~~~~~~~~~~~~~~~~~~~~~~~~~^^
  File "c:\Telegram Bot\AccountBot\.venv\Lib\site-packages\telebot\util.py", line 147, in raise_exceptions
    raise self.exception_info
  File "c:\Telegram Bot\AccountBot\.venv\Lib\site-packages\telebot\util.py", line 90, in run
    task(*args, **kwargs)
    ~~~~^^^^^^^^^^^^^^^^^
  File "c:\Telegram Bot\AccountBot\.venv\Lib\site-packages\telebot\__init__.py", line 6793, in _run_middlewares_and_handler
    result = handler['function'](message)
  File "bot.py", line 1643, in handle_history_report
    msg += get_current_month_report_message()
           ^^^^^^^^^^^^^^^^^^^^^^^^^^^^^^^^
NameError: name 'get_current_month_report_message' is not defined

2025-05-05 16:40:43,132 - Infinity polling exception: name 'get_current_month_report_message' is not defined
2025-05-05 16:40:43,139 - Exception traceback:
Traceback (most recent call last):
  File "c:\Telegram Bot\AccountBot\.venv\Lib\site-packages\telebot\__init__.py", line 957, in infinity_polling
    self.polling(non_stop=True, timeout=timeout, long_polling_timeout=long_polling_timeout,
    ~~~~~~~~~~~~^^^^^^^^^^^^^^^^^^^^^^^^^^^^^^^^^^^^^^^^^^^^^^^^^^^^^^^^^^^^^^^^^^^^^^^^^^^
                 logger_level=logger_level, allowed_updates=allowed_updates, restart_on_change=False,
                 ^^^^^^^^^^^^^^^^^^^^^^^^^^^^^^^^^^^^^^^^^^^^^^^^^^^^^^^^^^^^^^^^^^^^^^^^^^^^^^^^^^^^
                 *args, **kwargs)
                 ^^^^^^^^^^^^^^^^
  File "c:\Telegram Bot\AccountBot\.venv\Lib\site-packages\telebot\__init__.py", line 1045, in polling
    self.__threaded_polling(non_stop=non_stop, interval=interval, timeout=timeout, long_polling_timeout=long_polling_timeout,
    ~~~~~~~~~~~~~~~~~~~~~~~^^^^^^^^^^^^^^^^^^^^^^^^^^^^^^^^^^^^^^^^^^^^^^^^^^^^^^^^^^^^^^^^^^^^^^^^^^^^^^^^^^^^^^^^^^^^^^^^^^
                            logger_level=logger_level, allowed_updates=allowed_updates)
                            ^^^^^^^^^^^^^^^^^^^^^^^^^^^^^^^^^^^^^^^^^^^^^^^^^^^^^^^^^^^
  File "c:\Telegram Bot\AccountBot\.venv\Lib\site-packages\telebot\__init__.py", line 1120, in __threaded_polling
    raise e
  File "c:\Telegram Bot\AccountBot\.venv\Lib\site-packages\telebot\__init__.py", line 1082, in __threaded_polling
    self.worker_pool.raise_exceptions()
    ~~~~~~~~~~~~~~~~~~~~~~~~~~~~~~~~~^^
  File "c:\Telegram Bot\AccountBot\.venv\Lib\site-packages\telebot\util.py", line 147, in raise_exceptions
    raise self.exception_info
  File "c:\Telegram Bot\AccountBot\.venv\Lib\site-packages\telebot\util.py", line 90, in run
    task(*args, **kwargs)
    ~~~~^^^^^^^^^^^^^^^^^
  File "c:\Telegram Bot\AccountBot\.venv\Lib\site-packages\telebot\__init__.py", line 6793, in _run_middlewares_and_handler
    result = handler['function'](message)
  File "bot.py", line 1643, in handle_history_report
    msg += get_current_month_report_message()
           ^^^^^^^^^^^^^^^^^^^^^^^^^^^^^^^^
NameError: name 'get_current_month_report_message' is not defined

2025-05-05 16:40:50,987 - Infinity polling exception: name 'get_current_month_report_message' is not defined
2025-05-05 16:40:50,992 - Exception traceback:
Traceback (most recent call last):
  File "c:\Telegram Bot\AccountBot\.venv\Lib\site-packages\telebot\__init__.py", line 957, in infinity_polling
    self.polling(non_stop=True, timeout=timeout, long_polling_timeout=long_polling_timeout,
    ~~~~~~~~~~~~^^^^^^^^^^^^^^^^^^^^^^^^^^^^^^^^^^^^^^^^^^^^^^^^^^^^^^^^^^^^^^^^^^^^^^^^^^^
                 logger_level=logger_level, allowed_updates=allowed_updates, restart_on_change=False,
                 ^^^^^^^^^^^^^^^^^^^^^^^^^^^^^^^^^^^^^^^^^^^^^^^^^^^^^^^^^^^^^^^^^^^^^^^^^^^^^^^^^^^^
                 *args, **kwargs)
                 ^^^^^^^^^^^^^^^^
  File "c:\Telegram Bot\AccountBot\.venv\Lib\site-packages\telebot\__init__.py", line 1045, in polling
    self.__threaded_polling(non_stop=non_stop, interval=interval, timeout=timeout, long_polling_timeout=long_polling_timeout,
    ~~~~~~~~~~~~~~~~~~~~~~~^^^^^^^^^^^^^^^^^^^^^^^^^^^^^^^^^^^^^^^^^^^^^^^^^^^^^^^^^^^^^^^^^^^^^^^^^^^^^^^^^^^^^^^^^^^^^^^^^^
                            logger_level=logger_level, allowed_updates=allowed_updates)
                            ^^^^^^^^^^^^^^^^^^^^^^^^^^^^^^^^^^^^^^^^^^^^^^^^^^^^^^^^^^^
  File "c:\Telegram Bot\AccountBot\.venv\Lib\site-packages\telebot\__init__.py", line 1120, in __threaded_polling
    raise e
  File "c:\Telegram Bot\AccountBot\.venv\Lib\site-packages\telebot\__init__.py", line 1082, in __threaded_polling
    self.worker_pool.raise_exceptions()
    ~~~~~~~~~~~~~~~~~~~~~~~~~~~~~~~~~^^
  File "c:\Telegram Bot\AccountBot\.venv\Lib\site-packages\telebot\util.py", line 147, in raise_exceptions
    raise self.exception_info
  File "c:\Telegram Bot\AccountBot\.venv\Lib\site-packages\telebot\util.py", line 90, in run
    task(*args, **kwargs)
    ~~~~^^^^^^^^^^^^^^^^^
  File "c:\Telegram Bot\AccountBot\.venv\Lib\site-packages\telebot\__init__.py", line 6793, in _run_middlewares_and_handler
    result = handler['function'](message)
  File "bot.py", line 1643, in handle_history_report
    msg += get_current_month_report_message()
           ^^^^^^^^^^^^^^^^^^^^^^^^^^^^^^^^
NameError: name 'get_current_month_report_message' is not defined

